Workbook

Sheet P&L Cash Flow Annual
A2: Condition One
A3: Cash Flow Annual
B8: 2021 | C8: 2022 | D8: 2023 | E8: 2024 | F8: 2025 | G8: 2026 | H8: 2027
A10: Sales | L10: 216.15
A11: Gyms | B11: =SUM('P&L Cash Flow Monthly'!K11:V11) -> 133087.11 | C11: =+'P&L Cash Flow Monthly'!W11+'P&L Cash Flow Monthly'!X11+'P&L Cash Flow Monthly'!Y11+'P&L Cash Flow Monthly'!Z11+'P&L Cash Flow Monthly'!AA11+'P&L Cash Flow Monthly'!AB11+'P&L Cash Flow Monthly'!AC11+'P&L Cash Flow Monthly'!AD11+'P&L Cash Flow Monthly'!AE11+'P&L Cash Flow Monthly'!AF11+'P&L Cash Flow Monthly'!AG11+'P&L Cash Flow Monthly'!AH11 -> 127294.62 | D11: =+'P&L Cash Flow Monthly'!AI11+'P&L Cash Flow Monthly'!AJ11+'P&L Cash Flow Monthly'!AK11+'P&L Cash Flow Monthly'!AL11+'P&L Cash Flow Monthly'!AM11+'P&L Cash Flow Monthly'!AN11+'P&L Cash Flow Monthly'!AO11+'P&L Cash Flow Monthly'!AP11+'P&L Cash Flow Monthly'!AQ11+'P&L Cash Flow Monthly'!AR11+'P&L Cash Flow Monthly'!AS11+'P&L Cash Flow Monthly'!AT11 -> 90473.632 | E11: =+'P&L Cash Flow Monthly'!AU11+'P&L Cash Flow Monthly'!AV11+'P&L Cash Flow Monthly'!AW11+'P&L Cash Flow Monthly'!AX11+'P&L Cash Flow Monthly'!AY11+'P&L Cash Flow Monthly'!AZ11+'P&L Cash Flow Monthly'!BA11+'P&L Cash Flow Monthly'!BB11+'P&L Cash Flow Monthly'!BC11+'P&L Cash Flow Monthly'!BD11+'P&L Cash Flow Monthly'!BE11+'P&L Cash Flow Monthly'!BF11 -> 132743.05 | F11: =+'P&L Cash Flow Monthly'!BG11+'P&L Cash Flow Monthly'!BH11+'P&L Cash Flow Monthly'!BI11+'P&L Cash Flow Monthly'!BJ11+'P&L Cash Flow Monthly'!BK11+'P&L Cash Flow Monthly'!BL11+'P&L Cash Flow Monthly'!BM11+'P&L Cash Flow Monthly'!BN11+'P&L Cash Flow Monthly'!BO11+'P&L Cash Flow Monthly'!BP11+'P&L Cash Flow Monthly'!BQ11+'P&L Cash Flow Monthly'!BR11 -> 128606.49 | G11: =SUM('P&L Cash Flow Monthly'!BS11:CD11) -> 201224.06 | H11: =SUM('P&L Cash Flow Monthly'!CE11:CP11) -> 317836.39 | L11: 60
A12: E-commerce | B12: =SUM('P&L Cash Flow Monthly'!K12:V12) -> 910216.47 | C12: =+'P&L Cash Flow Monthly'!W12+'P&L Cash Flow Monthly'!X12+'P&L Cash Flow Monthly'!Y12+'P&L Cash Flow Monthly'!Z12+'P&L Cash Flow Monthly'!AA12+'P&L Cash Flow Monthly'!AB12+'P&L Cash Flow Monthly'!AC12+'P&L Cash Flow Monthly'!AD12+'P&L Cash Flow Monthly'!AE12+'P&L Cash Flow Monthly'!AF12+'P&L Cash Flow Monthly'!AG12+'P&L Cash Flow Monthly'!AH12 -> 891020.34 | D12: =+'P&L Cash Flow Monthly'!AI12+'P&L Cash Flow Monthly'!AJ12+'P&L Cash Flow Monthly'!AK12+'P&L Cash Flow Monthly'!AL12+'P&L Cash Flow Monthly'!AM12+'P&L Cash Flow Monthly'!AN12+'P&L Cash Flow Monthly'!AO12+'P&L Cash Flow Monthly'!AP12+'P&L Cash Flow Monthly'!AQ12+'P&L Cash Flow Monthly'!AR12+'P&L Cash Flow Monthly'!AS12+'P&L Cash Flow Monthly'!AT12 -> 633273.42 | E12: =+'P&L Cash Flow Monthly'!AU12+'P&L Cash Flow Monthly'!AV12+'P&L Cash Flow Monthly'!AW12+'P&L Cash Flow Monthly'!AX12+'P&L Cash Flow Monthly'!AY12+'P&L Cash Flow Monthly'!AZ12+'P&L Cash Flow Monthly'!BA12+'P&L Cash Flow Monthly'!BB12+'P&L Cash Flow Monthly'!BC12+'P&L Cash Flow Monthly'!BD12+'P&L Cash Flow Monthly'!BE12+'P&L Cash Flow Monthly'!BF12 -> 929159.32 | F12: =+'P&L Cash Flow Monthly'!BG12+'P&L Cash Flow Monthly'!BH12+'P&L Cash Flow Monthly'!BI12+'P&L Cash Flow Monthly'!BJ12+'P&L Cash Flow Monthly'!BK12+'P&L Cash Flow Monthly'!BL12+'P&L Cash Flow Monthly'!BM12+'P&L Cash Flow Monthly'!BN12+'P&L Cash Flow Monthly'!BO12+'P&L Cash Flow Monthly'!BP12+'P&L Cash Flow Monthly'!BQ12+'P&L Cash Flow Monthly'!BR12 -> 900203.45 | G12: =SUM('P&L Cash Flow Monthly'!BS12:CD12) -> 1408526.4 | H12: =SUM('P&L Cash Flow Monthly'!CE12:CP12) -> 2224812.7 | L12: 117.15
L13: 252
L14: 8.99
A15: Sales | B15: =SUM(B11:B12) -> 1043303.6 | C15: =SUM(C11:C12) -> 1018315 | D15: =SUM(D11:D12) -> 723747.05 | E15: =SUM(E11:E12) -> 1061902.4 | F15: =SUM(F11:F12) -> 1028809.9 | G15: =SUM(G11:G12) -> 1609750.5 | H15: =SUM(H11:H12) -> 2542649.1
A17: Cost of goods sold | B17: =SUM('P&L Cash Flow Monthly'!K17:V17) -> 748803.02 | C17: =+'P&L Cash Flow Monthly'!W17+'P&L Cash Flow Monthly'!X17+'P&L Cash Flow Monthly'!Y17+'P&L Cash Flow Monthly'!Z17+'P&L Cash Flow Monthly'!AA17+'P&L Cash Flow Monthly'!AB17+'P&L Cash Flow Monthly'!AC17+'P&L Cash Flow Monthly'!AD17+'P&L Cash Flow Monthly'!AE17+'P&L Cash Flow Monthly'!AF17+'P&L Cash Flow Monthly'!AG17+'P&L Cash Flow Monthly'!AH17 -> 716210.63 | D17: =+'P&L Cash Flow Monthly'!AI17+'P&L Cash Flow Monthly'!AJ17+'P&L Cash Flow Monthly'!AK17+'P&L Cash Flow Monthly'!AL17+'P&L Cash Flow Monthly'!AM17+'P&L Cash Flow Monthly'!AN17+'P&L Cash Flow Monthly'!AO17+'P&L Cash Flow Monthly'!AP17+'P&L Cash Flow Monthly'!AQ17+'P&L Cash Flow Monthly'!AR17+'P&L Cash Flow Monthly'!AS17+'P&L Cash Flow Monthly'!AT17 -> 436657.1 | E17: =+'P&L Cash Flow Monthly'!AU17+'P&L Cash Flow Monthly'!AV17+'P&L Cash Flow Monthly'!AW17+'P&L Cash Flow Monthly'!AX17+'P&L Cash Flow Monthly'!AY17+'P&L Cash Flow Monthly'!AZ17+'P&L Cash Flow Monthly'!BA17+'P&L Cash Flow Monthly'!BB17+'P&L Cash Flow Monthly'!BC17+'P&L Cash Flow Monthly'!BD17+'P&L Cash Flow Monthly'!BE17+'P&L Cash Flow Monthly'!BF17 -> 640677.47 | F17: =+'P&L Cash Flow Monthly'!BG17+'P&L Cash Flow Monthly'!BH17+'P&L Cash Flow Monthly'!BI17+'P&L Cash Flow Monthly'!BJ17+'P&L Cash Flow Monthly'!BK17+'P&L Cash Flow Monthly'!BL17+'P&L Cash Flow Monthly'!BM17+'P&L Cash Flow Monthly'!BN17+'P&L Cash Flow Monthly'!BO17+'P&L Cash Flow Monthly'!BP17+'P&L Cash Flow Monthly'!BQ17+'P&L Cash Flow Monthly'!BR17 -> 526500.94 | G17: =SUM('P&L Cash Flow Monthly'!BS17:CD17) -> 706946.13 | H17: =SUM('P&L Cash Flow Monthly'!CE17:CP17) -> 1116644.1
A19: Gross margin | B19: =+B15-B17 -> 294500.56 | C19: =+C15-C17 -> 302104.32 | D19: =+D15-D17 -> 287089.95 | E19: =+E15-E17 -> 421224.89 | F19: =+F15-F17 -> 502309.01 | G19: =+G15-G17 -> 902804.38 | H19: =+H15-H17 -> 1426005
A21: Expenses (see tab for detail) | B21: =SUM('P&L Cash Flow Monthly'!K21:V21) -> 654881.9 | C21: =+'P&L Cash Flow Monthly'!W21+'P&L Cash Flow Monthly'!X21+'P&L Cash Flow Monthly'!Y21+'P&L Cash Flow Monthly'!Z21+'P&L Cash Flow Monthly'!AA21+'P&L Cash Flow Monthly'!AB21+'P&L Cash Flow Monthly'!AC21+'P&L Cash Flow Monthly'!AD21+'P&L Cash Flow Monthly'!AE21+'P&L Cash Flow Monthly'!AF21+'P&L Cash Flow Monthly'!AG21+'P&L Cash Flow Monthly'!AH21 -> 648488.75 | D21: =+'P&L Cash Flow Monthly'!AI21+'P&L Cash Flow Monthly'!AJ21+'P&L Cash Flow Monthly'!AK21+'P&L Cash Flow Monthly'!AL21+'P&L Cash Flow Monthly'!AM21+'P&L Cash Flow Monthly'!AN21+'P&L Cash Flow Monthly'!AO21+'P&L Cash Flow Monthly'!AP21+'P&L Cash Flow Monthly'!AQ21+'P&L Cash Flow Monthly'!AR21+'P&L Cash Flow Monthly'!AS21+'P&L Cash Flow Monthly'!AT21 -> 365212.56 | E21: =+'P&L Cash Flow Monthly'!AU21+'P&L Cash Flow Monthly'!AV21+'P&L Cash Flow Monthly'!AW21+'P&L Cash Flow Monthly'!AX21+'P&L Cash Flow Monthly'!AY21+'P&L Cash Flow Monthly'!AZ21+'P&L Cash Flow Monthly'!BA21+'P&L Cash Flow Monthly'!BB21+'P&L Cash Flow Monthly'!BC21+'P&L Cash Flow Monthly'!BD21+'P&L Cash Flow Monthly'!BE21+'P&L Cash Flow Monthly'!BF21 -> 621502.52 | F21: =+'P&L Cash Flow Monthly'!BG21+'P&L Cash Flow Monthly'!BH21+'P&L Cash Flow Monthly'!BI21+'P&L Cash Flow Monthly'!BJ21+'P&L Cash Flow Monthly'!BK21+'P&L Cash Flow Monthly'!BL21+'P&L Cash Flow Monthly'!BM21+'P&L Cash Flow Monthly'!BN21+'P&L Cash Flow Monthly'!BO21+'P&L Cash Flow Monthly'!BP21+'P&L Cash Flow Monthly'!BQ21+'P&L Cash Flow Monthly'!BR21 -> 604084.51 | G21: =SUM('P&L Cash Flow Monthly'!BS21:CD21) -> 902177.81 | H21: =SUM('P&L Cash Flow Monthly'!CE21:CP21) -> 1297152.5
A23: Net income/EBITDA | B23: =+B19-B21 -> -360381.34 | C23: =+C19-C21 -> -346384.42 | D23: =+D19-D21 -> -78122.61 | E23: =+E19-E21 -> -200277.63 | F23: =+F19-F21 -> -101775.5 | G23: =+G19-G21 -> 626.56788 | H23: =+H19-H21 -> 128852.49
A25: Adjustments to convert net income to cash flow
A26: COGS | B26: =SUM('P&L Cash Flow Monthly'!K26:V26) -> 748803.02 | C26: =+'P&L Cash Flow Monthly'!W26+'P&L Cash Flow Monthly'!X26+'P&L Cash Flow Monthly'!Y26+'P&L Cash Flow Monthly'!Z26+'P&L Cash Flow Monthly'!AA26+'P&L Cash Flow Monthly'!AB26+'P&L Cash Flow Monthly'!AC26+'P&L Cash Flow Monthly'!AD26+'P&L Cash Flow Monthly'!AE26+'P&L Cash Flow Monthly'!AF26+'P&L Cash Flow Monthly'!AG26+'P&L Cash Flow Monthly'!AH26 -> 716210.63 | D26: =+'P&L Cash Flow Monthly'!AI26+'P&L Cash Flow Monthly'!AJ26+'P&L Cash Flow Monthly'!AK26+'P&L Cash Flow Monthly'!AL26+'P&L Cash Flow Monthly'!AM26+'P&L Cash Flow Monthly'!AN26+'P&L Cash Flow Monthly'!AO26+'P&L Cash Flow Monthly'!AP26+'P&L Cash Flow Monthly'!AQ26+'P&L Cash Flow Monthly'!AR26+'P&L Cash Flow Monthly'!AS26+'P&L Cash Flow Monthly'!AT26 -> 436657.1 | E26: =+'P&L Cash Flow Monthly'!AU26+'P&L Cash Flow Monthly'!AV26+'P&L Cash Flow Monthly'!AW26+'P&L Cash Flow Monthly'!AX26+'P&L Cash Flow Monthly'!AY26+'P&L Cash Flow Monthly'!AZ26+'P&L Cash Flow Monthly'!BA26+'P&L Cash Flow Monthly'!BB26+'P&L Cash Flow Monthly'!BC26+'P&L Cash Flow Monthly'!BD26+'P&L Cash Flow Monthly'!BE26+'P&L Cash Flow Monthly'!BF26 -> 640677.47 | F26: =+'P&L Cash Flow Monthly'!BG26+'P&L Cash Flow Monthly'!BH26+'P&L Cash Flow Monthly'!BI26+'P&L Cash Flow Monthly'!BJ26+'P&L Cash Flow Monthly'!BK26+'P&L Cash Flow Monthly'!BL26+'P&L Cash Flow Monthly'!BM26+'P&L Cash Flow Monthly'!BN26+'P&L Cash Flow Monthly'!BO26+'P&L Cash Flow Monthly'!BP26+'P&L Cash Flow Monthly'!BQ26+'P&L Cash Flow Monthly'!BR26 -> 526500.94 | G26: =SUM('P&L Cash Flow Monthly'!BS26:CD26) -> 706946.13 | H26: =SUM('P&L Cash Flow Monthly'!CE26:CP26) -> 1116644.1
A27: Payment for COGS | B27: =SUM('P&L Cash Flow Monthly'!K27:V27) -> -773403.12 | C27: =+'P&L Cash Flow Monthly'!W27+'P&L Cash Flow Monthly'!X27+'P&L Cash Flow Monthly'!Y27+'P&L Cash Flow Monthly'!Z27+'P&L Cash Flow Monthly'!AA27+'P&L Cash Flow Monthly'!AB27+'P&L Cash Flow Monthly'!AC27+'P&L Cash Flow Monthly'!AD27+'P&L Cash Flow Monthly'!AE27+'P&L Cash Flow Monthly'!AF27+'P&L Cash Flow Monthly'!AG27+'P&L Cash Flow Monthly'!AH27 -> -695924.67 | D27: =+'P&L Cash Flow Monthly'!AI27+'P&L Cash Flow Monthly'!AJ27+'P&L Cash Flow Monthly'!AK27+'P&L Cash Flow Monthly'!AL27+'P&L Cash Flow Monthly'!AM27+'P&L Cash Flow Monthly'!AN27+'P&L Cash Flow Monthly'!AO27+'P&L Cash Flow Monthly'!AP27+'P&L Cash Flow Monthly'!AQ27+'P&L Cash Flow Monthly'!AR27+'P&L Cash Flow Monthly'!AS27+'P&L Cash Flow Monthly'!AT27 -> -413845.89 | E27: =+'P&L Cash Flow Monthly'!AU27+'P&L Cash Flow Monthly'!AV27+'P&L Cash Flow Monthly'!AW27+'P&L Cash Flow Monthly'!AX27+'P&L Cash Flow Monthly'!AY27+'P&L Cash Flow Monthly'!AZ27+'P&L Cash Flow Monthly'!BA27+'P&L Cash Flow Monthly'!BB27+'P&L Cash Flow Monthly'!BC27+'P&L Cash Flow Monthly'!BD27+'P&L Cash Flow Monthly'!BE27+'P&L Cash Flow Monthly'!BF27 -> -694703.01 | F27: =+'P&L Cash Flow Monthly'!BG27+'P&L Cash Flow Monthly'!BH27+'P&L Cash Flow Monthly'!BI27+'P&L Cash Flow Monthly'!BJ27+'P&L Cash Flow Monthly'!BK27+'P&L Cash Flow Monthly'!BL27+'P&L Cash Flow Monthly'!BM27+'P&L Cash Flow Monthly'!BN27+'P&L Cash Flow Monthly'!BO27+'P&L Cash Flow Monthly'!BP27+'P&L Cash Flow Monthly'!BQ27+'P&L Cash Flow Monthly'!BR27 -> -489003.94 | G27: =SUM('P&L Cash Flow Monthly'!BS27:CD27) -> -774169.54 | H27: =SUM('P&L Cash Flow Monthly'!CE27:CP27) -> -1187655.1
A28: Marketing ad spend | B28: =SUM('P&L Cash Flow Monthly'!K28:V28) -> 175000 | C28: =+'P&L Cash Flow Monthly'!W28+'P&L Cash Flow Monthly'!X28+'P&L Cash Flow Monthly'!Y28+'P&L Cash Flow Monthly'!Z28+'P&L Cash Flow Monthly'!AA28+'P&L Cash Flow Monthly'!AB28+'P&L Cash Flow Monthly'!AC28+'P&L Cash Flow Monthly'!AD28+'P&L Cash Flow Monthly'!AE28+'P&L Cash Flow Monthly'!AF28+'P&L Cash Flow Monthly'!AG28+'P&L Cash Flow Monthly'!AH28 -> 118000 | D28: =+'P&L Cash Flow Monthly'!AI28+'P&L Cash Flow Monthly'!AJ28+'P&L Cash Flow Monthly'!AK28+'P&L Cash Flow Monthly'!AL28+'P&L Cash Flow Monthly'!AM28+'P&L Cash Flow Monthly'!AN28+'P&L Cash Flow Monthly'!AO28+'P&L Cash Flow Monthly'!AP28+'P&L Cash Flow Monthly'!AQ28+'P&L Cash Flow Monthly'!AR28+'P&L Cash Flow Monthly'!AS28+'P&L Cash Flow Monthly'!AT28 -> 79000 | E28: =+'P&L Cash Flow Monthly'!AU28+'P&L Cash Flow Monthly'!AV28+'P&L Cash Flow Monthly'!AW28+'P&L Cash Flow Monthly'!AX28+'P&L Cash Flow Monthly'!AY28+'P&L Cash Flow Monthly'!AZ28+'P&L Cash Flow Monthly'!BA28+'P&L Cash Flow Monthly'!BB28+'P&L Cash Flow Monthly'!BC28+'P&L Cash Flow Monthly'!BD28+'P&L Cash Flow Monthly'!BE28+'P&L Cash Flow Monthly'!BF28 -> 233000 | F28: =+'P&L Cash Flow Monthly'!BG28+'P&L Cash Flow Monthly'!BH28+'P&L Cash Flow Monthly'!BI28+'P&L Cash Flow Monthly'!BJ28+'P&L Cash Flow Monthly'!BK28+'P&L Cash Flow Monthly'!BL28+'P&L Cash Flow Monthly'!BM28+'P&L Cash Flow Monthly'!BN28+'P&L Cash Flow Monthly'!BO28+'P&L Cash Flow Monthly'!BP28+'P&L Cash Flow Monthly'!BQ28+'P&L Cash Flow Monthly'!BR28 -> 150000 | G28: =SUM('P&L Cash Flow Monthly'!BS28:CD28) -> 305000 | H28: =SUM('P&L Cash Flow Monthly'!CE28:CP28) -> 530000
A29: Payment for Marketing ad spend | B29: =SUM('P&L Cash Flow Monthly'!K29:V29) -> -170000 | C29: =+'P&L Cash Flow Monthly'!W29+'P&L Cash Flow Monthly'!X29+'P&L Cash Flow Monthly'!Y29+'P&L Cash Flow Monthly'!Z29+'P&L Cash Flow Monthly'!AA29+'P&L Cash Flow Monthly'!AB29+'P&L Cash Flow Monthly'!AC29+'P&L Cash Flow Monthly'!AD29+'P&L Cash Flow Monthly'!AE29+'P&L Cash Flow Monthly'!AF29+'P&L Cash Flow Monthly'!AG29+'P&L Cash Flow Monthly'!AH29 -> -118000 | D29: =+'P&L Cash Flow Monthly'!AI29+'P&L Cash Flow Monthly'!AJ29+'P&L Cash Flow Monthly'!AK29+'P&L Cash Flow Monthly'!AL29+'P&L Cash Flow Monthly'!AM29+'P&L Cash Flow Monthly'!AN29+'P&L Cash Flow Monthly'!AO29+'P&L Cash Flow Monthly'!AP29+'P&L Cash Flow Monthly'!AQ29+'P&L Cash Flow Monthly'!AR29+'P&L Cash Flow Monthly'!AS29+'P&L Cash Flow Monthly'!AT29 -> -77000 | E29: =+'P&L Cash Flow Monthly'!AU29+'P&L Cash Flow Monthly'!AV29+'P&L Cash Flow Monthly'!AW29+'P&L Cash Flow Monthly'!AX29+'P&L Cash Flow Monthly'!AY29+'P&L Cash Flow Monthly'!AZ29+'P&L Cash Flow Monthly'!BA29+'P&L Cash Flow Monthly'!BB29+'P&L Cash Flow Monthly'!BC29+'P&L Cash Flow Monthly'!BD29+'P&L Cash Flow Monthly'!BE29+'P&L Cash Flow Monthly'!BF29 -> -250000 | F29: =+'P&L Cash Flow Monthly'!BG29+'P&L Cash Flow Monthly'!BH29+'P&L Cash Flow Monthly'!BI29+'P&L Cash Flow Monthly'!BJ29+'P&L Cash Flow Monthly'!BK29+'P&L Cash Flow Monthly'!BL29+'P&L Cash Flow Monthly'!BM29+'P&L Cash Flow Monthly'!BN29+'P&L Cash Flow Monthly'!BO29+'P&L Cash Flow Monthly'!BP29+'P&L Cash Flow Monthly'!BQ29+'P&L Cash Flow Monthly'!BR29 -> -140000 | G29: =SUM('P&L Cash Flow Monthly'!BS29:CD29) -> -325000 | H29: =SUM('P&L Cash Flow Monthly'!CE29:CP29) -> -495000
A30: Initial up front costs | B30: =SUM('P&L Cash Flow Monthly'!K30:V30) -> 0 | C30: =+'P&L Cash Flow Monthly'!W30+'P&L Cash Flow Monthly'!X30+'P&L Cash Flow Monthly'!Y30+'P&L Cash Flow Monthly'!Z30+'P&L Cash Flow Monthly'!AA30+'P&L Cash Flow Monthly'!AB30+'P&L Cash Flow Monthly'!AC30+'P&L Cash Flow Monthly'!AD30+'P&L Cash Flow Monthly'!AE30+'P&L Cash Flow Monthly'!AF30+'P&L Cash Flow Monthly'!AG30+'P&L Cash Flow Monthly'!AH30 -> 0 | D30: =+'P&L Cash Flow Monthly'!AI30+'P&L Cash Flow Monthly'!AJ30+'P&L Cash Flow Monthly'!AK30+'P&L Cash Flow Monthly'!AL30+'P&L Cash Flow Monthly'!AM30+'P&L Cash Flow Monthly'!AN30+'P&L Cash Flow Monthly'!AO30+'P&L Cash Flow Monthly'!AP30+'P&L Cash Flow Monthly'!AQ30+'P&L Cash Flow Monthly'!AR30+'P&L Cash Flow Monthly'!AS30+'P&L Cash Flow Monthly'!AT30 -> 0 | E30: =+'P&L Cash Flow Monthly'!AU30+'P&L Cash Flow Monthly'!AV30+'P&L Cash Flow Monthly'!AW30+'P&L Cash Flow Monthly'!AX30+'P&L Cash Flow Monthly'!AY30+'P&L Cash Flow Monthly'!AZ30+'P&L Cash Flow Monthly'!BA30+'P&L Cash Flow Monthly'!BB30+'P&L Cash Flow Monthly'!BC30+'P&L Cash Flow Monthly'!BD30+'P&L Cash Flow Monthly'!BE30+'P&L Cash Flow Monthly'!BF30 -> 0 | F30: =+'P&L Cash Flow Monthly'!BG30+'P&L Cash Flow Monthly'!BH30+'P&L Cash Flow Monthly'!BI30+'P&L Cash Flow Monthly'!BJ30+'P&L Cash Flow Monthly'!BK30+'P&L Cash Flow Monthly'!BL30+'P&L Cash Flow Monthly'!BM30+'P&L Cash Flow Monthly'!BN30+'P&L Cash Flow Monthly'!BO30+'P&L Cash Flow Monthly'!BP30+'P&L Cash Flow Monthly'!BQ30+'P&L Cash Flow Monthly'!BR30 -> 0 | G30: =SUM('P&L Cash Flow Monthly'!BS30:CD30) -> 0 | H30: =SUM('P&L Cash Flow Monthly'!CE30:CP30) -> 0
A31: Tax distribution | B31: =SUM('P&L Cash Flow Monthly'!K31:V31) -> 0 | C31: =+'P&L Cash Flow Monthly'!W31+'P&L Cash Flow Monthly'!X31+'P&L Cash Flow Monthly'!Y31+'P&L Cash Flow Monthly'!Z31+'P&L Cash Flow Monthly'!AA31+'P&L Cash Flow Monthly'!AB31+'P&L Cash Flow Monthly'!AC31+'P&L Cash Flow Monthly'!AD31+'P&L Cash Flow Monthly'!AE31+'P&L Cash Flow Monthly'!AF31+'P&L Cash Flow Monthly'!AG31+'P&L Cash Flow Monthly'!AH31 -> 0 | D31: =+'P&L Cash Flow Monthly'!AI31+'P&L Cash Flow Monthly'!AJ31+'P&L Cash Flow Monthly'!AK31+'P&L Cash Flow Monthly'!AL31+'P&L Cash Flow Monthly'!AM31+'P&L Cash Flow Monthly'!AN31+'P&L Cash Flow Monthly'!AO31+'P&L Cash Flow Monthly'!AP31+'P&L Cash Flow Monthly'!AQ31+'P&L Cash Flow Monthly'!AR31+'P&L Cash Flow Monthly'!AS31+'P&L Cash Flow Monthly'!AT31 -> 0 | E31: =+'P&L Cash Flow Monthly'!AU31+'P&L Cash Flow Monthly'!AV31+'P&L Cash Flow Monthly'!AW31+'P&L Cash Flow Monthly'!AX31+'P&L Cash Flow Monthly'!AY31+'P&L Cash Flow Monthly'!AZ31+'P&L Cash Flow Monthly'!BA31+'P&L Cash Flow Monthly'!BB31+'P&L Cash Flow Monthly'!BC31+'P&L Cash Flow Monthly'!BD31+'P&L Cash Flow Monthly'!BE31+'P&L Cash Flow Monthly'!BF31 -> 0 | F31: =+'P&L Cash Flow Monthly'!BG31+'P&L Cash Flow Monthly'!BH31+'P&L Cash Flow Monthly'!BI31+'P&L Cash Flow Monthly'!BJ31+'P&L Cash Flow Monthly'!BK31+'P&L Cash Flow Monthly'!BL31+'P&L Cash Flow Monthly'!BM31+'P&L Cash Flow Monthly'!BN31+'P&L Cash Flow Monthly'!BO31+'P&L Cash Flow Monthly'!BP31+'P&L Cash Flow Monthly'!BQ31+'P&L Cash Flow Monthly'!BR31 -> 0 | G31: =SUM('P&L Cash Flow Monthly'!BS31:CD31) -> 0 | H31: =SUM('P&L Cash Flow Monthly'!CE31:CP31) -> 0
A32: Capital investment | B32: =SUM('P&L Cash Flow Monthly'!K32:V32) -> 400000 | C32: =+'P&L Cash Flow Monthly'!W32+'P&L Cash Flow Monthly'!X32+'P&L Cash Flow Monthly'!Y32+'P&L Cash Flow Monthly'!Z32+'P&L Cash Flow Monthly'!AA32+'P&L Cash Flow Monthly'!AB32+'P&L Cash Flow Monthly'!AC32+'P&L Cash Flow Monthly'!AD32+'P&L Cash Flow Monthly'!AE32+'P&L Cash Flow Monthly'!AF32+'P&L Cash Flow Monthly'!AG32+'P&L Cash Flow Monthly'!AH32 -> 285000 | D32: =+'P&L Cash Flow Monthly'!AI32+'P&L Cash Flow Monthly'!AJ32+'P&L Cash Flow Monthly'!AK32+'P&L Cash Flow Monthly'!AL32+'P&L Cash Flow Monthly'!AM32+'P&L Cash Flow Monthly'!AN32+'P&L Cash Flow Monthly'!AO32+'P&L Cash Flow Monthly'!AP32+'P&L Cash Flow Monthly'!AQ32+'P&L Cash Flow Monthly'!AR32+'P&L Cash Flow Monthly'!AS32+'P&L Cash Flow Monthly'!AT32 -> -14589 | E32: =+'P&L Cash Flow Monthly'!AU32+'P&L Cash Flow Monthly'!AV32+'P&L Cash Flow Monthly'!AW32+'P&L Cash Flow Monthly'!AX32+'P&L Cash Flow Monthly'!AY32+'P&L Cash Flow Monthly'!AZ32+'P&L Cash Flow Monthly'!BA32+'P&L Cash Flow Monthly'!BB32+'P&L Cash Flow Monthly'!BC32+'P&L Cash Flow Monthly'!BD32+'P&L Cash Flow Monthly'!BE32+'P&L Cash Flow Monthly'!BF32 -> 400000 | F32: =+'P&L Cash Flow Monthly'!BG32+'P&L Cash Flow Monthly'!BH32+'P&L Cash Flow Monthly'!BI32+'P&L Cash Flow Monthly'!BJ32+'P&L Cash Flow Monthly'!BK32+'P&L Cash Flow Monthly'!BL32+'P&L Cash Flow Monthly'!BM32+'P&L Cash Flow Monthly'!BN32+'P&L Cash Flow Monthly'!BO32+'P&L Cash Flow Monthly'!BP32+'P&L Cash Flow Monthly'!BQ32+'P&L Cash Flow Monthly'!BR32 -> -15000 | G32: =SUM('P&L Cash Flow Monthly'!BS32:CD32) -> 0 | H32: =SUM('P&L Cash Flow Monthly'!CE32:CP32) -> 0
A35: Annual cash flow | B35: =SUM(B23:B33) -> 20018.56 | C35: =SUM(C23:C33) -> -41098.458 | D35: =SUM(D23:D33) -> -67900.402 | E35: =SUM(E23:E33) -> 128696.84 | F35: =SUM(F23:F33) -> -69278.499 | G35: =SUM(G23:G33) -> -86596.848 | H35: =SUM(H23:H33) -> 92841.443
A37: Cash beginning of year | B37: ='P&L Cash Flow Monthly'!K37:K38 -> 179360.01 | C37: =+B39 -> 199378.57 | D37: =+C39 -> 158280.11 | E37: =+D39 -> 90379.707 | F37: =+E39 -> 219076.54 | G37: =+F39 -> 149798.04 | H37: =+G39 -> 63201.197
A39: Cash end of year | B39: =SUM(B35:B37) -> 199378.57 | C39: =SUM(C35:C37) -> 158280.11 | D39: =SUM(D35:D37) -> 90379.707 | E39: =SUM(E35:E37) -> 219076.54 | F39: =SUM(F35:F37) -> 149798.04 | G39: =SUM(G35:G37) -> 63201.197 | H39: =SUM(H35:H37) -> 156042.64
A42: Gross Profit % | B42: =B19/B15 -> 0.28227695 | C42: =C19/C15 -> 0.29667081 | D42: =D19/D15 -> 0.39667167 | E42: =E19/E15 -> 0.39667008 | F42: =F19/F15 -> 0.48824276 | G42: =G19/G15 -> 0.56083497 | H42: =H19/H15 -> 0.56083437
A44: Net Profit % | B44: =B23/B15 -> -0.34542328 | C44: =C23/C15 -> -0.34015451 | D44: =D23/D15 -> -0.10794187 | E44: =E23/E15 -> -0.18860267 | F44: =F23/F15 -> -0.098925459 | G44: =G23/G15 -> 0.00038923292 | H44: =H23/H15 -> 0.050676472

Sheet P&L Cash Flow Monthly
A2: Condition One | N2: Condition One | AA2: Condition One | AN2: Condition One
A3: Cash Flow Monthly | N3: Cash Flow Monthly | AA3: Cash Flow Monthly | AN3: Cash Flow Monthly
B8: 43951 | C8: 43982 | D8: 44012 | E8: 44043 | F8: 44074 | G8: 44104 | H8: 44135 | I8: 44165 | J8: 44196 | K8: 44227 | L8: 44255 | M8: 44286 | N8: 44316 | O8: 44347 | P8: 44377 | Q8: 44408 | R8: 44439 | S8: 44469 | T8: 44500 | U8: 44530 | V8: 44561 | W8: 44592 | X8: 44620 | Y8: 44651 | Z8: 44681 | AA8: 44712 | AB8: 44742 | AC8: 44773 | AD8: 44804 | AE8: 44834 | AF8: 44865 | AG8: 44895 | AH8: 44926 | AI8: 44957 | AJ8: 44985 | AK8: 45016 | AL8: 45046 | AM8: 45077 | AN8: 45107 | AO8: 45138 | AP8: 45169 | AQ8: 45199 | AR8: 45230 | AS8: 45260 | AT8: 45291 | AU8: 45322 | AV8: 45351 | AW8: 45382 | AX8: 45412 | AY8: 45443 | AZ8: 45473 | BA8: 45504 | BB8: 45535 | BC8: 45565 | BD8: 45596 | BE8: 45626 | BF8: 45657 | BG8: 45688 | BH8: 45716 | BI8: 45747 | BJ8: 45777 | BK8: 45808 | BL8: 45838 | BM8: 45869 | BN8: 45900 | BO8: 45930 | BP8: 45961 | BQ8: 45991 | BR8: 46022 | BS8: 46053 | BT8: 46081 | BU8: 46112 | BV8: 46142 | BW8: 46173 | BX8: 46203 | BY8: 46234 | BZ8: 46265 | CA8: 46295 | CB8: 46326 | CC8: 46356 | CD8: 46387 | CE8: 46418 | CF8: 46446 | CG8: 46477 | CH8: 46507 | CI8: 46538 | CJ8: 46568 | CK8: 46599 | CL8: 46630 | CM8: 46660 | CN8: 46691 | CO8: 46721 | CP8: 46752 | CQ8: 46753 | CR8: 46754 | CS8: 46755
A10: Sales
A11: Gyms | C11: =+'Rev 2'!V13 -> 65.084987 | D11: =+'Rev 2'!W13 -> 782.69595 | E11: =+'Rev 2'!X13 -> 1192.7594 | F11: =+'Rev 2'!Y13 -> 1545.4617 | G11: =+'Rev 2'!Z13 -> 1523.2111 | H11: =+'Rev 2'!AA13 -> 2184.1721 | I11: =+'Rev 2'!AB13 -> 4280.355 | J11: =+'Rev 2'!AC13 -> 4144.1221 | ... CP11: =+'Rev 2'!DI13 -> 31502.36
A12: E-commerce | B12: 2770.21 | C12: 3324.68 | D12: 5292.33 | E12: 10996.11 | F12: 17836.54 | G12: 20272.6 | H12: 20869.28 | I12: 34588 | J12: 22500 | K12: 25500 | L12: =+'Rev 2'!AE18 -> 59003.591 | M12: =+'Rev 2'!AF18 -> 83902.828 | N12: =+'Rev 2'!AG18 -> 83920.74 | O12: =+'Rev 2'!AH18 -> 73894.487 | P12: =+'Rev 2'!AI18 -> 63868.234 | Q12: =+'Rev 2'!AJ18 -> 59100.083 | R12: =+'Rev 2'!AK18 -> 67881.498 | S12: =+'Rev 2'!AL18 -> 83839.023 | ... CP12: =+'Rev 2'!DI18 -> 220513.02
A15: Sales | B15: =SUM(B11:B13) -> 2770.21 | C15: =SUM(C11:C13) -> 3389.765 | D15: =SUM(D11:D13) -> 6075.026 | E15: =SUM(E11:E13) -> 12188.869 | F15: =SUM(F11:F13) -> 19382.002 | G15: =SUM(G11:G13) -> 21795.811 | H15: =SUM(H11:H13) -> 23053.452 | I15: =SUM(I11:I13) -> 38868.355 | ... CS15: =SUM(CS11:CS13) -> 0
A17: Cost of goods sold | B17: =+'Rev 2'!U21*COGS!B28 -> 0 | C17: =+'Rev 2'!V21*COGS!B28 -> 440.90018 | D17: =+COGS!B23 -> 5339.791 | E17: =+COGS!C23 -> 8139.1572 | F17: =+COGS!D23 -> 9928.9536 | G17: =+COGS!E23 -> 9785.9566 | H17: =+COGS!F23 -> 14033.733 | I17: =+COGS!G23 -> 24081.317 | J17: =+COGS!H23 -> 23314.78 | K17: =+COGS!I23 -> 37659.495 | ... CP17: =+COGS!CN23 -> 110676.53
A19: Gross margin | B19: =+B15-B17 -> 2770.21 | C19: =+C15-C17 -> 2948.8648 | D19: =+D15-D17 -> 735.23493 | E19: =+E15-E17 -> 4049.7121 | F19: =+F15-F17 -> 9453.0481 | G19: =+G15-G17 -> 12009.854 | H19: =+H15-H17 -> 9019.7195 | I19: =+I15-I17 -> 14787.038 | ... CP19: =+CP15-CP17 -> 141338.84
A21: Expenses (see tab for detail) | B21: =+'Expenses 2'!B102 -> 29693.703 | C21: =+'Expenses 2'!C102 -> 26720.251 | D21: =+'Expenses 2'!D102 -> 26835.315 | E21: =+'Expenses 2'!E102 -> 25597.293 | F21: =+'Expenses 2'!F102 -> 25905.519 | G21: =+'Expenses 2'!G102 -> 27008.951 | H21: =+'Expenses 2'!H102 -> 32062.84 | I21: =+'Expenses 2'!I102 -> 40740.509 | ... CP21: =+'Expenses 2'!CP102 -> 118398.86
A23: Net income/EBITDA | B23: =+B19-B21 -> -26923.494 | C23: =+C19-C21 -> -23771.387 | D23: =+D19-D21 -> -26100.08 | E23: =+E19-E21 -> -21547.581 | F23: =+F19-F21 -> -16452.471 | G23: =+G19-G21 -> -14999.096 | H23: =+H19-H21 -> -23043.121 | I23: =+I19-I21 -> -25953.471 | ... CP23: =+CP19-CP21 -> 22939.985
A25: Adjustments to convert net income to cash flow
A26: COGS | B26: =+B17 -> 0 | C26: =+C17 -> 440.90018 | D26: =+D17 -> 5339.791 | E26: =+E17 -> 8139.1572 | F26: =+F17 -> 9928.9536 | G26: =+G17 -> 9785.9566 | H26: =+H17 -> 14033.733 | I26: =+I17 -> 24081.317 | ... CP26: =+CP17 -> 110676.53
A27: Payment for COGS | B27: =-COGS!B32-COGS!B23 -> -6120.4822 | C27: =-COGS!C23 -> -8139.1572 | D27: =-COGS!D23 -> -9928.9536 | E27: =-COGS!E23 -> -9785.9566 | F27: =-COGS!F23 -> -14033.733 | G27: =-COGS!G23 -> -24081.317 | H27: =-COGS!H23 -> -23314.78 | I27: =-COGS!I23 -> -37659.495 | J27: =-COGS!J23 -> -47427.648 | ... CP27: =-COGS!CP23 -> -110676.53
A28: Marketing ad spend | B28: ='Expenses 2'!B89 -> 1500 | C28: ='Expenses 2'!C89 -> 3500 | D28: ='Expenses 2'!D89 -> 3500 | E28: ='Expenses 2'!E89 -> 2000 | F28: ='Expenses 2'!F89 -> 2000 | G28: ='Expenses 2'!G89 -> 3000 | H28: ='Expenses 2'!H89 -> 5000 | I28: ='Expenses 2'!I89 -> 12000 | ... AG28: ='Expenses 2'!AG89 -> 10000 | AH28: ='Expenses 2'!AH28 -> 10000 | AI28: ='Expenses 2'!AI28 -> 10000 | AJ28: ='Expenses 2'!AJ28 -> 5000 | AK28: ='Expenses 2'!AK28 -> 5000 | AL28: ='Expenses 2'!AL28 -> 5000 | AM28: ='Expenses 2'!AM28 -> 7000 | AN28: ='Expenses 2'!AN28 -> 7000 | AO28: ='Expenses 2'!AO28 -> 7000 | ... CP28: ='Expenses 2'!CP28 -> 50000
A29: Payment for Marketing ad spend | B29: =-'Expenses 2'!C89 -> -3500 | C29: =-'Expenses 2'!D89 -> -3500 | D29: =-'Expenses 2'!E89 -> -2000 | E29: =-'Expenses 2'!F89 -> -2000 | F29: =-'Expenses 2'!G89 -> -3000 | G29: =-'Expenses 2'!H89 -> -5000 | H29: =-'Expenses 2'!I89 -> -12000 | I29: =-'Expenses 2'!J89 -> -2000 | ... AF29: =-'Expenses 2'!AG89 -> -10000 | AG29: =-'Expenses 2'!AH28 -> -10000 | AH29: =-'Expenses 2'!AI28 -> -10000 | AI29: =-'Expenses 2'!AJ28 -> -5000 | AJ29: =-'Expenses 2'!AK28 -> -5000 | AK29: =-'Expenses 2'!AL28 -> -5000 | AL29: =-'Expenses 2'!AM28 -> -7000 | AM29: =-'Expenses 2'!AN28 -> -7000 | AN29: =-'Expenses 2'!AO28 -> -7000 | ... CO29: =-'Expenses 2'!CP28 -> -50000 | CP29: =-'Expenses 2'!CQ89 -> 0
A30: Initial up front costs | B30: =-'Up front costs'!B20 -> 0
A31: Tax distribution | K31: =-Taxes!D32 -> 0 | L31: =-Taxes!E32 -> 0 | M31: =-Taxes!F32 -> 0 | N31: =-Taxes!G32 -> 0 | O31: =-Taxes!H32 -> 0 | P31: =-Taxes!I32 -> 0 | Q31: =-Taxes!J32 -> 0 | R31: =-Taxes!K32 -> 0 | ... CP31: =-Taxes!CI32 -> 0
A32: Capital investment | B32: 375000 | J32: 100000 | N32: 10000 | O32: 50000 | P32: 80000 | R32: 260000 | W32: 150000 | AA32: 35000 | AB32: 100000 | AL32: 25000 | AN32: -139589 | AO32: 25000 | AR32: 25000 | AT32: 50000 | AU32: 100000 | AV32: 150000 | AW32: 0 | AX32: 0 | AY32: 0 | AZ32: 0 | BA32: 0 | BC32: -15000 | BD32: 80000 | BE32: 100000 | BF32: -15000 | BG32: -15000 | BH32: -15000 | BI32: -15000 | BJ32: -15000 | BK32: -15000 | BL32: -15000 | BM32: -15000 | BN32: -15000 | BO32: -15000 | BP32: -15000 | BQ32: -15000 | BR32: 150000 | BT32: 0 | BU32: 0 | BV32: 0 | BW32: 0 | BX32: 0 | BY32: 0 | BZ32: 0 | CA32: 0 | CB32: 0 | CC32: 0 | CD32: 0 | CE32: 0 | CF32: 0 | CG32: 0 | CH32: 0 | CI32: 0 | CJ32: 0
L33: Note 1
A35: Monthly cash flow | B35: =SUM(B23:B33) -> 339956.02 | C35: =SUM(C23:C33) -> -31469.644 | D35: =SUM(D23:D33) -> -29189.242 | E35: =SUM(E23:E33) -> -23194.38 | F35: =SUM(F23:F33) -> -21557.25 | G35: =SUM(G23:G33) -> -31294.457 | H35: =SUM(H23:H33) -> -39324.169 | I35: =SUM(I23:I33) -> -29531.649 | ... CP35: =SUM(CP23:CP33) -> 72939.985
A37: Cash beginning of month | B37: 6965 | C37: =+B39 -> 346921.02 | D37: =+C39 -> 315451.38 | E37: =+D39 -> 286262.14 | F37: =+E39 -> 263067.76 | G37: =+F39 -> 241510.51 | H37: =+G39 -> 210216.05 | I37: =+H39 -> 170891.88 | J37: =+I39 -> 141360.23 | ... CP37: =+CO39 -> 83102.656
A39: Cash end of month | B39: =SUM(B35:B37) -> 346921.02 | C39: =SUM(C35:C37) -> 315451.38 | D39: =SUM(D35:D37) -> 286262.14 | E39: =SUM(E35:E37) -> 263067.76 | F39: =SUM(F35:F37) -> 241510.51 | G39: =SUM(G35:G37) -> 210216.05 | H39: =SUM(H35:H37) -> 170891.88 | I39: =SUM(I35:I37) -> 141360.23 | ... CP39: =SUM(CP35:CP37) -> 156042.64
A42: Gross Profit % | B42: =B19/B15 -> 1 | C42: =C19/C15 -> 0.86993193 | D42: =D19/D15 -> 0.12102581 | E42: =E19/E15 -> 0.33224674 | F42: =F19/F15 -> 0.487723 | G42: =G19/G15 -> 0.55101664 | H42: =H19/H15 -> 0.39125245 | I42: =I19/I15 -> 0.38043899 | ... CP42: =CP19/CP15 -> 0.5608342
A44: Net Profit % | B44: =B23/B15 -> -9.7189359 | C44: =C23/C15 -> -7.0126946 | D44: =D23/D15 -> -4.2962911 | E44: =E23/E15 -> -1.767808 | F44: =F23/F15 -> -0.84885302 | G44: =G23/G15 -> -0.68816416 | H44: =H23/H15 -> -0.99955186 | I44: =I23/I15 -> -0.66772755 | ... CP44: =CP23/CP15 -> 0.09102613
BQ49: =SUM(BF32,BG32,BH32,BJ32,BK32,BL32,BM31,BM31,BM32,BN32,BO32,BP32,BQ32,) -> -165000

Sheet Rev 2
A2: Condition One
A3: I
D8: March | E8: April | F8: May | G8: June | H8: July | I8: August | J8: Spetember | K8: October | L8: Novemeber | M8: December | N8: January | O8: February | P8: March | Q8: April | R8: May | S8: June | T8: 43647 | U8: =+'P&L Cash Flow Monthly'!B8 -> 43951 | V8: =+'P&L Cash Flow Monthly'!C8 -> 43982 | W8: =+'P&L Cash Flow Monthly'!D8 -> 44012 | X8: =+'P&L Cash Flow Monthly'!E8 -> 44043 | Y8: =+'P&L Cash Flow Monthly'!F8 -> 44074 | Z8: =+'P&L Cash Flow Monthly'!G8 -> 44104 | AA8: =+'P&L Cash Flow Monthly'!H8 -> 44135 | AB8: =+'P&L Cash Flow Monthly'!I8 -> 44165 | ... DI8: =+'P&L Cash Flow Monthly'!CP8 -> 46752 | DJ8: 46783 | DK8: 46811 | DL8: 46843
A13: Effect on gross sales by increasing sales over base selling procew per bar | V13: =+V21*$I25+$J29 -> 65.084987 | W13: =+W21*$I25+$J29 -> 782.69595 | X13: =+X21*$I25+$J29 -> 1192.7594 | Y13: =+Y21*$I25+$J29 -> 1545.4617 | Z13: =+Z21*$I25+$J29 -> 1523.2111 | AA13: =+AA21*$I25+$J29 -> 2184.1721 | AB13: =+AB21*$I25+$J29 -> 4280.355 | AC13: =+AC21*$I25+$J29 -> 4144.1221 | ... DL13: =+DL21*$I25+$J29 -> 0.5
A16: E-Commerce Revenue
A17: Number of customers added | T17: 80 | V17: ='Expenses 2'!C89/V42 -> 11.666667 | W17: ='Expenses 2'!D89/W42 -> 129.62963 | X17: ='Expenses 2'!E89/X42 -> 74.074074 | Y17: ='Expenses 2'!F89/Y42 -> 74.074074 | Z17: ='Expenses 2'!G89/Z42 -> 111.11111 | AA17: ='Expenses 2'!H89/AA42 -> 185.18519 | AB17: ='Expenses 2'!I89/AB42 -> 444.44444 | AC17: ='Expenses 2'!J89/AC42 -> 74.074074 | ... AZ17: ='Expenses 2'!AG89/AZ42 -> 285.71429 | BA17: ='Expenses 2'!AH28/BA42 -> 285.71429 | BB17: ='Expenses 2'!AI28/BB42 -> 250 | BC17: ='Expenses 2'!AJ28/BC42 -> 125 | BD17: ='Expenses 2'!AK28/BD42 -> 125 | BE17: ='Expenses 2'!AL28/BE42 -> 125 | BF17: ='Expenses 2'!AM28/BF42 -> 175 | BG17: ='Expenses 2'!AN28/BG42 -> 175 | BH17: ='Expenses 2'!AO28/BH42 -> 200 | ... DI17: ='Expenses 2'!CP28/DI42 -> 1250
A18: Ecommcer rev | V18: =+V530 -> 452.09491 | W18: =+W530 -> 5475.3717 | X18: =+X530 -> 8345.8155 | Y18: =+Y530 -> 10814.732 | Z18: =+Z530 -> 10658.978 | AA18: =+AA530 -> 15285.705 | AB18: =+AB530 -> 29958.985 | AC18: =+AC530 -> 29005.355 | ... DI18: =+DI530 -> 220513.02
A19: Bars sold | T19: =SUM(T17*10) -> 800 | V19: =+V18*$B32 -> 129.16997 | W19: =+W18*$B32 -> 1564.3919 | X19: =+X18*$B32 -> 2384.5187 | Y19: =+Y18*$B32 -> 3089.9233 | Z19: =+Z18*$B32 -> 3045.4222 | AA19: =+AA18*$B32 -> 4367.3442 | AB19: =+AB18*$B32 -> 8559.71 | AC19: =+AC18*$B32 -> 8287.2442 | ... DI19: =+DI18*$B32 -> 63003.719 | DJ19: =DI19 -> 63003.719 | DK19: =DJ19 -> 63003.719 | DL19: =DK19 -> 63003.719
A21: Total Bars Sold per month | V21: =+V19+V14 -> 129.16997 | W21: =+W19+W14 -> 1564.3919 | X21: =+X19+X14 -> 2384.5187 | Y21: =+Y19+Y14 -> 3089.9233 | Z21: =+Z19+Z14 -> 3045.4222 | AA21: =+AA19+AA14 -> 4367.3442 | AB21: =+AB19+AB14 -> 8559.71 | AC21: =+AC19+AC14 -> 8287.2442 | ... DI21: =+DI19+DI14 -> 63003.719
A23: Total Gross Revenue per month. | I23: % sales | V23: =+V13+V18 -> 517.17989 | W23: =+W13+W18 -> 6258.0676 | X23: =+X13+X18 -> 9538.5749 | Y23: =+Y13+Y18 -> 12360.193 | Z23: =+Z13+Z18 -> 12182.189 | AA23: =+AA13+AA18 -> 17469.877 | AB23: =+AB13+AB18 -> 34239.34 | AC23: =+AC13+AC18 -> 33149.477 | ... DI23: =+DI13+DI18 -> 252015.38 | DJ23: =DI23 -> 252015.38 | DK23: =DJ23 -> 252015.38 | DL23: =DK23 -> 252015.38
D24: Base selling price | H24: =+B31 -> 3.5 | I24: 0.5 | J24: =+H24*I24 -> 1.75
D25: Higher selling price | H25: 4.5 | I25: 0.5 | J25: =+H25*I25 -> 2.25
H26: 0
D28: New weighted average selling price | J28: =+J24+J25 -> 4
D29: Adjustment to selling proce | J29: =+J28-B31 -> 0.5
A30: ECOMM Figures
A31: Price per bar | B31: 3.5 | C31: 3.7
A32: Bars per $1 of sales | B32: =1/B31 -> 0.28571429
A35: GYMs figures
A36: Whole sale price per bar | B36: 2.5
A37: Bars per minum order | B37: 60
A38: Minum gym order value | B38: =SUM(B36*B37) -> 150
A42: Cost to Acquire customer | U42: 30 | V42: 300 | W42: 27 | X42: 27 | Y42: 27 | Z42: 27 | AA42: 27 | AB42: 27 | AC42: 27 | AD42: 24 | AE42: 24 | AF42: 24 | AG42: 27 | AH42: 27 | AI42: 27 | AJ42: 27 | AK42: 27 | AL42: 27 | AM42: 27 | AN42: 30 | AO42: 30 | AP42: 27 | AQ42: 27 | AR42: 27 | AS42: 27 | AT42: 27 | AU42: 27 | AV42: 27 | AW42: 27 | AX42: 27 | AY42: 27 | AZ42: 35 | BA42: 35 | BB42: 40 | BC42: 40 | BD42: 40 | BE42: 40 | BF42: 40 | BG42: 40 | BH42: 35 | BI42: 35 | BJ42: 35 | BK42: 35 | BL42: 40 | BM42: 40 | BN42: 40 | BO42: 50 | BP42: 50 | BQ42: 50 | BR42: 45 | BS42: 45 | BT42: 40 | BU42: 35 | BV42: 35 | BW42: 35 | BX42: 40 | BY42: 40 | BZ42: 35 | CA42: 35 | CB42: 35 | CC42: 35 | CD42: 35 | CE42: 35 | CF42: 35 | CG42: 35 | CH42: 35 | CI42: 35 | CJ42: 35 | CK42: 35 | CL42: 35 | CM42: 35 | CN42: 35 | CO42: 35 | CP42: 35 | CQ42: 35 | CR42: 35 | CS42: 35 | CT42: 35 | CU42: 35 | CV42: 35 | CW42: 35 | CX42: 40 | CY42: 40 | CZ42: 40 | DA42: 40 | DB42: 40 | DC42: 40 | DD42: 40 | DE42: 40 | DF42: 40 | DG42: 40 | DH42: 40 | DI42: 40
A44: Cost to aquire gym | B44: =SUM(CAC!B10) -> 20
A47: Total gyms | B47: =SUM(D10:M10) -> 0
A49: Gym attrition rate per year | B49: 0.1
A53: New customers | U53: ='Expenses 2'!B89/U42 -> 50 | V53: ='Expenses 2'!C89/V42 -> 11.666667 | W53: ='Expenses 2'!D89/W42 -> 129.62963 | X53: ='Expenses 2'!E89/X42 -> 74.074074 | Y53: ='Expenses 2'!F89/Y42 -> 74.074074 | Z53: ='Expenses 2'!G89/Z42 -> 111.11111 | AA53: ='Expenses 2'!H89/AA42 -> 185.18519 | AB53: ='Expenses 2'!I89/AB42 -> 444.44444 | ... AZ53: ='Expenses 2'!AG89/AZ42 -> 285.71429 | BA53: ='Expenses 2'!AH28/BA42 -> 285.71429 | BB53: ='Expenses 2'!AI28/BB42 -> 250 | BC53: ='Expenses 2'!AJ28/BC42 -> 125 | BD53: ='Expenses 2'!AK28/BD42 -> 125 | BE53: ='Expenses 2'!AL28/BE42 -> 125 | BF53: ='Expenses 2'!AM28/BF42 -> 175 | BG53: ='Expenses 2'!AN28/BG42 -> 175 | BH53: ='Expenses 2'!AO28/BH42 -> 200 | ... DI53: ='Expenses 2'!CP28/DI42 -> 1250
A54: Total active customers | U54: =U53 -> 50 | V54: =U54+V53 -> 61.666667 | W54: =V54+W53 -> 191.2963 | X54: =W54+X53 -> 265.37037 | Y54: =X54+Y53 -> 339.44444 | Z54: =Y54+Z53 -> 450.55556 | AA54: =Z54+AA53 -> 635.74074 | AB54: =AA54+AB53 -> 1080.1852 | AC54: =AB54+AC53 -> 1154.2593 | ... DI54: =DH54+DI53 -> 45886.931
B56: # years | U56: % new customers | V56: # months | W56: Total LT value | X56: Monthly LT value | Y56: wieghted average
A57: Values for each new customers | AB57: First months sales new customers | AD57: =($U58*$X58+$U59*$X59+$U60*$X60+$U61*$X61)*AD53 -> 24219.37 | AE57: =($U58*$X58+$U59*$X59+$U60*$X60+$U61*$X61)*AE53 -> 27448.619 | AF57: =($U58*$X58+$U59*$X59+$U60*$X60+$U61*$X61)*AF53 -> 27448.619 | AG57: =($U58*$X58+$U59*$X59+$U60*$X60+$U61*$X61)*AG53 -> 21528.329 | AH57: =($U58*$X58+$U59*$X59+$U60*$X60+$U61*$X61)*AH53 -> 14352.219 | AI57: =($U58*$X58+$U59*$X59+$U60*$X60+$U61*$X61)*AI53 -> 14352.219 | AJ57: =($U58*$X58+$U59*$X59+$U60*$X60+$U61*$X61)*AJ53 -> 14352.219 | AK57: =($U58*$X58+$U59*$X59+$U60*$X60+$U61*$X61)*AK53 -> 21528.329 | ... DI57: =($U58*$X58+$U59*$X59+$U60*$X60+$U61*$X61)*DI53 -> 48438.74
B58: 3.5 | U58: 0.01 | V58: =+B58*12 -> 42 | W58: 1774 | X58: =+W58/V58 -> 42.238095 | Y58: =W58*U58 -> 17.74
B59: 2.5 | U59: 0.035 | V59: =+B59*12 -> 30 | W59: 1075 | X59: =+W59/V59 -> 35.833333 | Y59: =W59*U59 -> 37.625 | AB59: Social media account manager | AD59: 2000 | AE59: 2000 | AF59: 2000 | AG59: =IF(AG57<83333,AG57*0.1,100000/12) -> 2152.8329 | AH59: =IF(AH57<83333,AH57*0.1,100000/12) -> 1435.2219 | AI59: =IF(AI57<83333,AI57*0.1,100000/12) -> 1435.2219 | AJ59: =IF(AJ57<83333,AJ57*0.1,100000/12) -> 1435.2219 | AK59: =IF(AK57<83333,AK57*0.1,100000/12) -> 2152.8329 | AL59: =IF(AL57<83333,AL57*0.1,100000/12) -> 2870.4439 | AM59: =IF(AM57<83333,AM57*0.1,100000/12) -> 4305.6658 | AN59: =IF(AN57<83333,AN57*0.1,100000/12) -> 1033.3598 | ... DI59: =IF(DI57<83333,DI57*0.1,100000/12) -> 4843.874
B60: 1.5 | U60: 0.08 | V60: =+B60*12 -> 18 | W60: 598 | X60: =+W60/V60 -> 33.222222 | Y60: =W60*U60 -> 47.84
B61: 0.25 | U61: 0.875 | V61: =+B61*12 -> 3 | W61: 118 | X61: =+W61/V61 -> 39.333333 | Y61: =W61*U61 -> 103.25
U64: =SUM(U58:U63) -> 1 | Y64: =SUM(Y58:Y61) -> 206.455
U68: From
A69: Returning Customers | U69: =+U8 -> 43951 | V69: =+#REF!-#REF!*#REF!/12 -> #REF! | W69: =IF(V69>0.005,(V69-#REF!*#REF!/12),0) -> #REF! | X69: =IF(W69>0.005,(W69-#REF!*#REF!/12),0) -> #REF! | Y69: =IF(X69>0.005,(X69-#REF!*#REF!/12),0) -> #REF! | Z69: =IF(Y69>0.005,(Y69-#REF!*#REF!/12),0) -> #REF! | AA69: =IF(Z69>0.005,(Z69-#REF!*#REF!/12),0) -> #REF! | AB69: =IF(AA69>0.005,(AA69-#REF!*#REF!/12),0) -> #REF! | AC69: =IF(AB69>0.005,(AB69-#REF!*#REF!/12),0) -> #REF! | AD69: =IF(AC69>0.005,(AC69-#REF!*#REF!/12),0) -> #REF! | ... CB69: =IF(CA69>0.005,(CA69-#REF!*#REF!/12),0) -> #REF!
U70: 43982 | V70: =+U17*#REF! -> #REF! | W70: =IF(V70>0.005,(V70-$V70*#REF!/12),0) -> #REF! | X70: =IF(W70>0.005,(W70-$V70*#REF!/12),0) -> #REF! | Y70: =IF(X70>0.005,(X70-$V70*#REF!/12),0) -> #REF! | Z70: =IF(Y70>0.005,(Y70-$V70*#REF!/12),0) -> #REF! | AA70: =IF(Z70>0.005,(Z70-$V70*#REF!/12),0) -> #REF! | AB70: =IF(AA70>0.005,(AA70-$V70*#REF!/12),0) -> #REF! | AC70: =IF(AB70>0.005,(AB70-$V70*#REF!/12),0) -> #REF! | AD70: =IF(AC70>0.005,(AC70-$V70*#REF!/12),0) -> #REF! | ... CB70: =IF(CA70>0.005,(CA70-$V70*#REF!/12),0) -> #REF!
U71: 44012 | W71: =+V$17*#REF! -> #REF! | X71: =IF(W71>0.005,(W71-$W71*#REF!/12),0) -> #REF! | Y71: =IF(X71>0.005,(X71-$W71*#REF!/12),0) -> #REF! | Z71: =IF(Y71>0.005,(Y71-$W71*#REF!/12),0) -> #REF! | AA71: =IF(Z71>0.005,(Z71-$W71*#REF!/12),0) -> #REF! | AB71: =IF(AA71>0.005,(AA71-$W71*#REF!/12),0) -> #REF! | AC71: =IF(AB71>0.005,(AB71-$W71*#REF!/12),0) -> #REF! | AD71: =IF(AC71>0.005,(AC71-$W71*#REF!/12),0) -> #REF! | AE71: =IF(AD71>0.005,(AD71-$W71*#REF!/12),0) -> #REF! | ... CB71: =IF(CA71>0.005,(CA71-$W71*#REF!/12),0) -> #REF!
U72: 44043 | X72: =+W$17*#REF! -> #REF! | Y72: =IF(X72>0.005,(X72-$X72*#REF!/12),0) -> #REF! | Z72: =IF(Y72>0.005,(Y72-$X72*#REF!/12),0) -> #REF! | AA72: =IF(Z72>0.005,(Z72-$X72*#REF!/12),0) -> #REF! | AB72: =IF(AA72>0.005,(AA72-$X72*#REF!/12),0) -> #REF! | AC72: =IF(AB72>0.005,(AB72-$X72*#REF!/12),0) -> #REF! | AD72: =IF(AC72>0.005,(AC72-$X72*#REF!/12),0) -> #REF! | AE72: =IF(AD72>0.005,(AD72-$X72*#REF!/12),0) -> #REF! | AF72: =IF(AE72>0.005,(AE72-$X72*#REF!/12),0) -> #REF! | ... CB72: =IF(CA72>0.005,(CA72-$X72*#REF!/12),0) -> #REF!
...

Sheet COGS
A3: COGS Projections
B9: =+'P&L Cash Flow Monthly'!B8 -> 43951 | C9: =+'P&L Cash Flow Monthly'!C8 -> 43982 | D9: =+'P&L Cash Flow Monthly'!D8 -> 44012 | E9: =+'P&L Cash Flow Monthly'!E8 -> 44043 | F9: =+'P&L Cash Flow Monthly'!F8 -> 44074 | G9: =+'P&L Cash Flow Monthly'!G8 -> 44104 | H9: =+'P&L Cash Flow Monthly'!H8 -> 44135 | I9: =+'P&L Cash Flow Monthly'!I8 -> 44165 | ... CP9: =+'P&L Cash Flow Monthly'!CP8 -> 46752
A10: Labor & Fullment cost per bar | B10: 2.25 | C10: 2.25 | D10: 2.05 | E10: 2.05 | F10: 2.05 | G10: 1.65 | H10: 1.65 | I10: 1.65 | J10: 1.65 | K10: 1.65 | L10: 1.65 | M10: 1.65 | N10: 1.65 | O10: 1.65 | P10: 1.65 | Q10: 1.65 | R10: 1.65 | S10: 1.65 | T10: 1.65 | U10: 1.65 | V10: 1.65 | W10: 1.65 | X10: 1.65 | Y10: 1.65 | Z10: 1.65 | AA10: 1.65 | AB10: 1.65 | AC10: 1.65 | AD10: 1.65 | AE10: 1.65 | AF10: 1.65 | AG10: 1.25 | AH10: 1.25 | AI10: 1.25 | AJ10: 1.25 | AK10: 1.25 | AL10: 1.25 | AM10: 1.25 | AN10: 1.25 | AO10: 1.25 | AP10: 1.25 | AQ10: 1.25 | AR10: 1.25 | AS10: 1.25 | AT10: 1.25 | AU10: 1.25 | AV10: 1.25 | AW10: 1.25 | AX10: 1.25 | AY10: 1.25 | AZ10: 1.25 | BA10: 1.25 | BB10: 1.25 | BC10: 1.25 | BD10: 1.25 | BE10: 1.25 | BF10: 1.25 | BG10: 0.94 | BH10: 0.94 | BI10: 0.94 | BJ10: 0.94 | BK10: 0.94 | BL10: 0.94 | BM10: 0.94 | BN10: 0.94 | BO10: 0.94 | BP10: 0.94 | BQ10: 0.94 | BR10: 0.94 | BS10: 0.94 | BT10: 0.94 | BU10: 0.94 | BV10: 0.94 | BW10: 0.94 | BX10: 0.94 | BY10: 0.94 | BZ10: 0.94 | CA10: 0.94 | CB10: 0.94 | CC10: 0.94 | CD10: 0.94 | CE10: 0.94 | CF10: 0.94 | CG10: 0.94 | CH10: 0.94 | CI10: 0.94 | CJ10: 0.94 | CK10: 0.94 | CL10: 0.94 | CM10: 0.94 | CN10: 0.94 | CO10: 0.94 | CP10: 0.94
A12: Ingredients and packging cost per bar | B12: =+$B41 -> 1.1633333 | C12: =+$B41 -> 1.1633333 | D12: =+$B41 -> 1.1633333 | E12: =+$B41 -> 1.1633333 | F12: =+$B41 -> 1.1633333 | G12: =+$B41 -> 1.1633333 | H12: =+$B41 -> 1.1633333 | I12: =+$B41 -> 1.1633333 | ... L12: =+$B41 -> 1.1633333 | M12: =+B41 -> 1.1633333 | N12: =+B41 -> 1.1633333 | O12: =+$B41 -> 1.1633333 | P12: =+$B41 -> 1.1633333 | Q12: =+$B41 -> 1.1633333 | R12: =+$B41 -> 1.1633333 | S12: =+$B41 -> 1.1633333 | T12: =+$B41 -> 1.1633333 | U12: =+$B41 -> 1.1633333 | V12: =+$B41 -> 1.1633333 | ... BL12: =+$B41 -> 1.1633333 | BM12: =+$C41 -> 0.81666667 | BN12: =+$C41 -> 0.81666667 | BO12: =+$C41 -> 0.81666667 | BP12: =+$C41 -> 0.81666667 | BQ12: =+$C41 -> 0.81666667 | BR12: =+$C41 -> 0.81666667 | BS12: =+$C41 -> 0.81666667 | BT12: =+$C41 -> 0.81666667 | ... CP12: =+$C41 -> 0.81666667
A14: total cost per bar | B14: =+B10+$B41 -> 3.4133333 | C14: =+C10+$B41 -> 3.4133333 | D14: =+D10+$B41 -> 3.2133333 | E14: =+E10+$B41 -> 3.2133333 | F14: =+F10+$B41 -> 3.2133333 | G14: =+G10+$B41 -> 2.8133333 | H14: =+H10+$B41 -> 2.8133333 | I14: =SUM(I10:I12) -> 2.8133333 | J14: =SUM(J10:J12) -> 2.8133333 | K14: =SUM(K10:K12) -> 2.8133333 | L14: =SUM(L10:L12) -> 2.8133333 | M14: =SUM(M10:M12) -> 2.8133333 | N14: =SUM(N10:N12) -> 2.8133333 | O14: =SUM(O10:O12) -> 2.8133333 | P14: =SUM(P10:P12) -> 2.8133333 | ... CP14: =SUM(CP10:CP12) -> 1.7566667
A17: For sales in month | B17: =+D9 -> 44012 | C17: =+E9 -> 44043 | D17: =+F9 -> 44074 | E17: =+G9 -> 44104 | F17: =+H9 -> 44135 | G17: =+I9 -> 44165 | H17: =+J9 -> 44196 | I17: =+K9 -> 44227 | ... CP17: =+CR9
A19: Produced third month prior to sale
A20: Ingredietns Purchase three months forward
A21: # bars produced | B21: =+'Rev 2'!W19 -> 1564.3919 | C21: =+'Rev 2'!X19 -> 2384.5187 | D21: =+'Rev 2'!Y19 -> 3089.9233 | E21: =+'Rev 2'!Z19 -> 3045.4222 | F21: =+'Rev 2'!AA19 -> 4367.3442 | G21: =+'Rev 2'!AB19 -> 8559.71 | H21: =+'Rev 2'!AC19 -> 8287.2442 | I21: =+'Rev 2'!AD19 -> 13386.077 | ... CP21: =+'Rev 2'!DK19 -> 63003.719
B23: =+B21*B14 -> 5339.791 | C23: =+C21*C14 -> 8139.1572 | D23: =+D21*D14 -> 9928.9536 | E23: =+E21*E14 -> 9785.9566 | F23: =+F21*F14 -> 14033.733 | G23: =+G21*G14 -> 24081.317 | H23: =+H21*H14 -> 23314.78 | I23: =+I21*I14 -> 37659.495 | ... CP23: =+CP21*CP14 -> 110676.53
A26: Additional production month 1
A27: # bars to be sold months 1 and 2 | B27: =+'Rev 2'!V19+'Rev 2'!W19 -> 1693.5619
A28: Cost per bar | B28: =+B14 -> 3.4133333
B29: =+B27*B28 -> 5780.6912
A30: Cost of inventory on hand | B30: -5000
A31: Additional production costs for first
A32: two months sales | B32: =SUM(B29:B30) -> 780.6912
C34: economy of scale
C35: %30 reduction
A36: Bar cost break down per bar
A37: ingredients | B37: 0.95 | C37: 0.65
A38: flow wrap and label | B38: 0.13 | C38: 0.1
A39: display box | B39: =0.15/6 -> 0.025 | C39: =+B39*0.8 -> 0.02
A40: Shipper box | B40: =0.35/6 -> 0.058333333 | C40: =+B40*0.8 -> 0.046666667
A41: total material cost per bar | B41: =SUM(B37:B40) -> 1.1633333 | C41: =SUM(C37:C40) -> 0.81666667

Sheet Expenses 2
A4: Expense Projections
B9: =+'P&L Cash Flow Monthly'!B8 -> 43951 | C9: =+'P&L Cash Flow Monthly'!C8 -> 43982 | D9: =+'P&L Cash Flow Monthly'!D8 -> 44012 | E9: =+'P&L Cash Flow Monthly'!E8 -> 44043 | F9: =+'P&L Cash Flow Monthly'!F8 -> 44074 | G9: =+'P&L Cash Flow Monthly'!G8 -> 44104 | H9: =+'P&L Cash Flow Monthly'!H8 -> 44135 | I9: =+'P&L Cash Flow Monthly'!I8 -> 44165 | ... CP9: =+'P&L Cash Flow Monthly'!CP8 -> 46752
A10: Expense
A13: Salaries
A14: Executive
A15: COO | AJ15: 0 | AL15: 0 | AU15: 2000 | AV15: 2000 | AW15: 2000 | AX15: 2000 | AY15: 2000 | AZ15: 2000 | BA15: 2000 | BB15: 2000 | BC15: 2000 | BD15: 2000 | BE15: 2000 | BF15: 2000 | BG15: 2000 | BH15: 2000 | BI15: 2000 | BJ15: 2000 | BK15: 2000 | BL15: 2000 | BM15: 2000 | BN15: 3000 | BO15: 3000 | BP15: 3000 | BQ15: 3000 | BR15: 3000 | BS15: 3000 | BT15: 3000 | BU15: 3000 | BV15: 3000 | BW15: 3000 | BX15: 3000 | BY15: 3000 | BZ15: 3000 | CA15: 3000 | CB15: 3000 | CC15: 3000 | CD15: 3000 | CE15: 6000 | CF15: 6000 | CG15: 6000 | CH15: 6000 | CI15: 6000 | CJ15: 6000 | CK15: 6000 | CL15: 6000 | CM15: 6000 | CN15: 6000 | CO15: 6000 | CP15: 6000
A16: CFO
A17: Sales
A18: Director
A19: Sales representive | AO19: 0
A20: Marketing | AO20: 0
A21: Director | AJ21: 0 | AK21: 0 | AL21: 0 | AM21: 0 | AN21: 0 | AO21: 0 | AP21: 0 | AQ21: 0 | AR21: 0 | AS21: 0 | AT21: 0 | AU21: 0 | AV21: 0 | AW21: 0 | AX21: 0 | AY21: 0 | AZ21: 0 | BA21: 0 | BB21: 0 | BC21: 0 | BD21: 0 | BE21: 0 | BF21: 0 | BG21: 0 | BH21: 0 | BI21: 0 | BJ21: 0 | BK21: 0 | BL21: 0 | BM21: 0 | BN21: 0 | BO21: 0 | BP21: 0 | BQ21: 0 | BR21: 0 | BS21: 0 | BT21: 0 | BU21: 0 | BV21: 0 | BW21: 0 | BX21: 0 | BY21: 0 | BZ21: 0 | CA21: 0 | CB21: 0 | CC21: 0 | CD21: 0 | CE21: 0 | CF21: 0 | CG21: 0 | CH21: 0 | CI21: 0 | CJ21: 0 | CK21: 0 | CL21: 0 | CM21: 0 | CN21: 0 | CO21: 0 | CP21: 0 | CQ21: 0
A22: SEO manager | AI22: 1500 | AJ22: 1500 | AK22: 1500 | AL22: 1500 | AM22: 1500 | AN22: 1500 | AO22: 1500 | AP22: 1500 | AQ22: 1500 | AR22: 1500 | AS22: 1500 | AT22: 1500 | AU22: 1500 | AV22: 1500 | AW22: 1500 | AX22: 1500 | AY22: 1500 | AZ22: 1500 | BA22: 1500 | BB22: 1500 | BC22: 1500 | BD22: 1500 | BE22: 1500 | BF22: 1500 | BG22: 1500 | BH22: 1500 | BI22: 1500 | BJ22: 1500 | BK22: 1500 | BL22: 1500 | BM22: 1500 | BN22: 1500 | BO22: 1500 | BP22: 1500 | BQ22: 3000 | BR22: 3000 | BS22: 3000 | BT22: 3000 | BU22: 3000 | BV22: 3000 | BW22: 3000 | BX22: 3000 | BY22: 3000 | BZ22: 3000 | CA22: 3000 | CB22: 3000 | CC22: 3000 | CD22: 3000 | CE22: 3000 | CF22: 3000 | CG22: 3000 | CH22: 3000 | CI22: 3000 | CJ22: 3000 | CK22: 3000 | CL22: 3000 | CM22: 3000 | CN22: 3000 | CO22: 3000 | CP22: 3000
A23: Social media manager | B23: 3000 | C23: 3000 | D23: 3000 | E23: 3000 | F23: 3000 | G23: 3000 | H23: 3000 | I23: 3000 | J23: 3000 | K23: 3000 | L23: 3000 | M23: 3000 | N23: 3000 | O23: 3000 | P23: 3000 | Q23: 3000 | R23: 3000 | S23: 3000 | T23: 3000 | U23: 3000 | V23: 3000 | W23: 3000 | X23: 3000 | Y23: 3000 | Z23: 3000 | AA23: 3000 | AB23: 3000 | AC23: 3000 | AD23: 3000 | AE23: 3000 | AF23: 3000 | AG23: 3000 | AI23: 1500 | AJ23: 1500 | AK23: 1500 | AL23: 1500 | AM23: 1500 | AN23: 1500 | AO23: 1500 | AP23: 1500 | AQ23: 1500 | AR23: 1500 | AS23: 1500 | AT23: 1500 | AU23: 1500 | AV23: 1500 | AW23: 1500 | AX23: 1500 | AY23: 1500 | AZ23: 1500 | BA23: 1500 | BB23: 1500 | BC23: 1500 | BD23: 1500 | BE23: 1500 | BF23: 1500 | BG23: 1500 | BH23: 1500 | BI23: 1500 | BJ23: 1500 | BK23: 1500 | BL23: 1500 | BM23: 1500 | BN23: 1500 | BO23: 1500 | BP23: 2000 | BQ23: 2000 | BR23: 2000 | BS23: 2000 | BT23: 2000 | BU23: 2000 | BV23: 2000 | BW23: 2000 | BX23: 2000 | BY23: 2000 | BZ23: 2000 | CA23: 2000 | CB23: 2000 | CC23: 2000 | CD23: 2000 | CE23: 2000 | CF23: 2000 | CG23: 2000 | CH23: 2000 | CI23: 2000 | CJ23: 2000 | CK23: 2000 | CL23: 2000 | CM23: 2000 | CN23: 2000 | CO23: 2000 | CP23: 2000
A24: Tier 1 customer support
A26: Marketing expenses
A27: Content creation | AH27: 0 | AI27: 1000 | AJ27: 1000 | AK27: 1000 | AL27: 1000 | AM27: 1000 | AN27: 1000 | AO27: 1000 | AP27: 10000 | AQ27: 2000 | AR27: 2000 | AS27: 2000 | AT27: 2000 | AU27: 2000 | AV27: 2000 | AW27: 2000 | AX27: 2000 | AY27: 2000 | AZ27: 2000 | BA27: 2000 | BB27: 5000 | BC27: 5000 | BD27: 5000 | BE27: 5000 | BF27: 5000 | BG27: 5000 | BH27: 5000 | BI27: 5000 | BJ27: 3000 | BK27: 3000 | BL27: 3000 | BM27: 3000 | BN27: 3000 | BO27: 3000 | BP27: 3000 | BQ27: 3000 | BR27: 3000 | BS27: 3000 | BT27: 3000 | BU27: 3000 | BV27: 3000 | BW27: 3000 | BX27: 3000 | BY27: 3000 | BZ27: 3000 | CA27: 3000 | CB27: 3000 | CC27: 3000 | CD27: 3000 | CE27: 3000 | CF27: 3000 | CG27: 3000 | CH27: 10000 | CI27: 10000 | CJ27: 10000 | CK27: 10000 | CL27: 10000 | CM27: 10000 | CN27: 10000 | CO27: 10000 | CP27: 10000
A28: Marketing at spend | AH28: 10000 | AI28: 10000 | AJ28: 5000 | AK28: 5000 | AL28: 5000 | AM28: 7000 | AN28: 7000 | AO28: 7000 | AP28: 7000 | AQ28: 7000 | AR28: 7000 | AS28: 7000 | AT28: 5000 | AU28: 8000 | AV28: 15000 | AW28: 25000 | AX28: 25000 | AY28: 25000 | AZ28: 25000 | BA28: 25000 | BB28: 25000 | BC28: 15000 | BD28: 15000 | BE28: 15000 | BF28: 15000 | BG28: 25000 | BH28: 10000 | BI28: 10000 | BJ28: 10000 | BK28: 10000 | BL28: 10000 | BM28: 10000 | BN28: 10000 | BO28: 10000 | BP28: 15000 | BQ28: 15000 | BR28: 15000 | BS28: 15000 | BT28: 15000 | BU28: 20000 | BV28: 25000 | BW28: 25000 | BX28: 25000 | BY28: 30000 | BZ28: 30000 | CA28: 30000 | CB28: 30000 | CC28: 30000 | CD28: 30000 | CE28: 35000 | CF28: 35000 | CG28: 40000 | CH28: 40000 | CI28: 40000 | CJ28: 45000 | CK28: 45000 | CL28: 50000 | CM28: 50000 | CN28: 50000 | CO28: 50000 | CP28: 50000
A29: Instagram
A30: Facebook
A31: TikTok
A32: Brand Ambassador | AH32: 0 | AI32: 0 | AJ32: 0 | AK32: 0 | AL32: 0 | AM32: 0 | AN32: 0 | AO32: 0 | AP32: 0 | AQ32: 0 | AR32: 0 | AS32: 0 | AT32: 0 | AU32: 0 | AV32: 0 | AW32: 0 | AX32: 0 | AY32: 0 | AZ32: 0 | BA32: 0 | BB32: 0 | BC32: 0 | BD32: 0 | BE32: 0 | BF32: 0 | BG32: 0 | BH32: 0 | BI32: 0 | BJ32: 0 | BK32: 0 | BL32: 0 | BM32: 0 | BN32: 0 | BO32: 0 | BP32: 0 | BQ32: 0 | BR32: 0 | BS32: 0 | BT32: 0 | BU32: 0 | BV32: 0 | BW32: 0 | BX32: 0 | BY32: 0 | BZ32: 0 | CA32: 0 | CB32: 0 | CC32: 0 | CD32: 0 | CE32: 0 | CF32: 0 | CG32: 0 | CH32: 0 | CI32: 0 | CJ32: 0 | CK32: 0 | CL32: 0 | CM32: 0 | CN32: 0 | CO32: 0 | CP32: 0 | CQ32: 0 | CR32: 0 | CS32: 0 | CT32: 0 | CU32: 0 | CV32: 0 | CW32: 0 | CX32: 0
A33: Operations
A34: Website maintenance and design | AH34: 1500 | AI34: 1500 | AJ34: 1500 | AK34: 1500 | AL34: 1500 | AM34: 1500 | AN34: 1500 | AO34: 1500 | AP34: 1500 | AQ34: 1500 | AR34: 1500 | AS34: 1500 | AT34: 1500 | AU34: 2500 | AV34: 2500 | AW34: 2500 | AX34: 2500 | AY34: 2500 | AZ34: 2500 | BA34: 2500 | BB34: 2500 | BC34: 2500 | BD34: 2500 | BE34: 2500 | BF34: 2500 | BG34: 2500 | BH34: 2500 | BI34: 2500 | BJ34: 2500 | BK34: 2500 | BL34: 2500 | BM34: 2500 | BN34: 2500 | BO34: 2500 | BP34: 2500 | BQ34: 2500 | BR34: 2500 | BS34: 2500 | BT34: 2500 | BU34: 2500 | BV34: 2500 | BW34: 2500 | BX34: 2500 | BY34: 2500 | BZ34: 2500 | CA34: 2500 | CB34: 2500 | CC34: 2500 | CD34: 2500 | CE34: 2500 | CF34: 2500 | CG34: 2500 | CH34: 2500 | CI34: 2500 | CJ34: 2500 | CK34: 2500 | CL34: 2500 | CM34: 2500 | CN34: 2500 | CO34: 2500 | CP34: 2500
A35: Website hosting
A36: Website utility and operations platform | AH36: 0 | AI36: 0 | AJ36: 0 | AK36: 0 | AL36: 0 | AM36: 0 | AN36: 0 | AO36: 0 | AP36: 0 | AQ36: 0 | AR36: 0 | AS36: 0 | AT36: 0 | AU36: 0 | AV36: 2000 | AW36: 2000 | AX36: 2000 | AY36: 2000 | AZ36: 2000 | BA36: 2000 | BB36: 2000 | BC36: 2000 | BD36: 2000 | BE36: 2000 | BF36: 2000 | BG36: 2000 | BH36: 2000 | BI36: 2000 | BJ36: 2000 | BK36: 2000 | BL36: 2000 | BM36: 2000 | BN36: 2000 | BO36: 2000 | BP36: 2000 | BQ36: 1000 | BR36: 1000 | BS36: 1000 | BT36: 1000 | BU36: 1000 | BV36: 1000 | BW36: 1000 | BX36: 1000 | BY36: 1000 | BZ36: 1000 | CA36: 1000 | CB36: 1000 | CC36: 1000 | CD36: 1000 | CE36: 1000 | CF36: 1000 | CG36: 1000 | CH36: 1000 | CI36: 1000 | CJ36: 1000 | CK36: 1000 | CL36: 1000 | CM36: 1000 | CN36: 1000 | CO36: 1000 | CP36: 1000
A37: Marketing events and sponsorships
A38: Public relations | AI38: 0 | AJ38: 0 | AK38: 0 | AL38: 0 | AM38: 0 | AN38: 0 | AO38: 0 | AP38: 0 | AQ38: 0 | AR38: 0 | AS38: 0 | AT38: 0 | AU38: 0 | AV38: 0 | AW38: 0 | AX38: 0 | AY38: 0 | AZ38: 0 | BA38: 0 | BB38: 0 | BC38: 0 | BD38: 0 | BE38: 0 | BF38: 0 | BG38: 0 | BH38: 0 | BI38: 0 | BJ38: 0 | BK38: 0 | BL38: 0 | BM38: 0 | BN38: 0 | BO38: 0 | BP38: 0 | BQ38: 0 | BR38: 0 | BS38: 0 | BT38: 0 | BU38: 0 | BV38: 0 | BW38: 0 | BX38: 0 | BY38: 0 | BZ38: 0 | CA38: 0 | CB38: 0 | CC38: 0 | CD38: 0 | CE38: 0 | CF38: 0 | CG38: 0 | CH38: 0 | CI38: 0 | CJ38: 0 | CK38: 0 | CL38: 0 | CM38: 0 | CN38: 0 | CO38: 0 | CP38: 0
A40: Selling and G&A expenses
A41: Salaries
A42: Officer, administration and customer service | AH42: 3000 | AI42: 3000 | AJ42: 3000 | AK42: 3000 | AL42: 3000 | AM42: 3000 | AN42: 3000 | AO42: 3000 | AP42: 3000 | AQ42: 3000 | AR42: 3000 | AS42: 3000 | AT42: 3000 | AU42: 3000 | AV42: 3000 | AW42: 3000 | AX42: 3000 | AY42: 3000 | AZ42: 3000 | BA42: 3000 | BB42: 3000 | BC42: 3000 | BD42: 3000 | BE42: 3000 | BF42: 3000 | BG42: 5000 | BH42: 5000 | BI42: 5000 | BJ42: 5000 | BK42: 5000 | BL42: 5000 | BM42: 5000 | BN42: 5000 | BO42: 5000 | BP42: 5000 | BQ42: 5000 | BR42: 5000 | BS42: 5000 | BT42: 5000 | BU42: 5000 | BV42: 5000 | BW42: 5000 | BX42: 5000 | BY42: 5000 | BZ42: 5000 | CA42: 5000 | CB42: 5000 | CC42: 5000 | CD42: 5000 | CE42: 5000 | CF42: 5000 | CG42: 5000 | CH42: 5000 | CI42: 5000 | CJ42: 5000 | CK42: 5000 | CL42: 5000 | CM42: 5000 | CN42: 5000 | CO42: 5000 | CP42: 5000
A43: Credit card processing fees | AH43: =+'P&L Cash Flow Monthly'!AH15*0.04 -> 3593.9679 | AI43: =+'P&L Cash Flow Monthly'!AI15*0.04 -> 3113.516 | AJ43: =+'P&L Cash Flow Monthly'!AJ15*0.04 -> 2813.6804 | AK43: =+'P&L Cash Flow Monthly'!AK15*0.04 -> 2489.2217 | AL43: =+'P&L Cash Flow Monthly'!AL15*0.04 -> 2171.707 | AM43: =+'P&L Cash Flow Monthly'!AM15*0.04 -> 2227.1673 | AN43: =+'P&L Cash Flow Monthly'!AN15*0.04 -> 2303.862 | AO43: =+'P&L Cash Flow Monthly'!AO15*0.04 -> 2380.6574 | ... CP43: =+'P&L Cash Flow Monthly'!CP15*0.04 -> 10080.615
A44: Warehousing | AH44: 200 | AI44: 200 | AJ44: 200 | AK44: 200 | AL44: 200 | AM44: 200 | AN44: 200 | AO44: 200 | AP44: 200 | AQ44: 200 | AR44: 200 | AS44: 200 | AT44: 200 | AU44: 1200 | AV44: 1200 | AW44: 1200 | AX44: 1200 | AY44: 1200 | AZ44: 1200 | BA44: 1200 | BB44: 1200 | BC44: 1200 | BD44: 1200 | BE44: 1200 | BF44: 1200 | BG44: 1200 | BH44: 1200 | BI44: 1200 | BJ44: 1200 | BK44: 1200 | BL44: 1200 | BM44: 1200 | BN44: 1200 | BO44: 1200 | BP44: 1200 | BQ44: 2400 | BR44: 2400 | BS44: 5500 | BT44: 5500 | BU44: 5500 | BV44: 5500 | BW44: 5500 | BX44: 5500 | BY44: 5500 | BZ44: 5500 | CA44: 5500 | CB44: 5500 | CC44: 5500 | CD44: 5500 | CE44: 5500 | CF44: 5500 | CG44: 5500 | CH44: 5500 | CI44: 5500 | CJ44: 5500 | CK44: 5500 | CL44: 5500 | CM44: 5500 | CN44: 5500 | CO44: 5500 | CP44: 5500
A45: E-commerce platform (ie Shopify) | AH45: 1200 | AI45: 1200 | AJ45: 1200 | AK45: 1200 | AL45: 1200 | AM45: 1200 | AN45: 1200 | AO45: 1200 | AP45: 1200 | AQ45: 1200 | AR45: 1200 | AS45: 1200 | AT45: 1200 | AU45: 1200 | AV45: 1200 | AW45: 1200 | AX45: 1200 | AY45: 1200 | AZ45: 1200 | BA45: 1200 | BB45: 1200 | BC45: 1200 | BD45: 1200 | BE45: 1200 | BF45: 1200 | BG45: 1200 | BH45: 1200 | BI45: 1200 | BJ45: 1200 | BK45: 1200 | BL45: 1200 | BM45: 1200 | BN45: 1200 | BO45: 1200 | BP45: 1200 | BQ45: 1200 | BR45: 1200 | BS45: 1200 | BT45: 1200 | BU45: 1200 | BV45: 1200 | BW45: 1200 | BX45: 1200 | BY45: 1200 | BZ45: 1200 | CA45: 1200 | CB45: 1200 | CC45: 1200 | CD45: 1200 | CE45: 1200 | CF45: 1200 | CG45: 1200 | CH45: 1200 | CI45: 1200 | CJ45: 1200 | CK45: 1200 | CL45: 1200 | CM45: 1200 | CN45: 1200 | CO45: 1200 | CP45: 1200
A46: Rent | AH46: 1300 | AI46: 1300 | AJ46: 1300 | AK46: 1300 | AL46: 1300 | AM46: 1300 | AN46: 1300 | AO46: 1300 | AP46: 1300 | AQ46: 1300 | AR46: 1300 | AS46: 1300 | AT46: 1300 | AU46: 1300 | AV46: 1300 | AW46: 1300 | AX46: 1300 | AY46: 1300 | AZ46: 1300 | BA46: 1300 | BB46: 1300 | BC46: 1300 | BD46: 1300 | BE46: 1300 | BF46: 1300 | BG46: 1300 | BH46: 1300 | BI46: 1300 | BJ46: 1300 | BK46: 1300 | BL46: 1300 | BM46: 1300 | BN46: 1300 | BO46: 1300 | BP46: 1300 | BQ46: 5000 | BR46: 5000 | BS46: 5000 | BT46: 5000 | BU46: 5000 | BV46: 5000 | BW46: 5000 | BX46: 5000 | BY46: 5000 | BZ46: 5000 | CA46: 5000 | CB46: 5000 | CC46: 5000 | CD46: 5000 | CE46: 5000 | CF46: 5000 | CG46: 5000 | CH46: 5000 | CI46: 5000 | CJ46: 5000 | CK46: 5000 | CL46: 5000 | CM46: 5000 | CN46: 5000 | CO46: 5000 | CP46: 5000
A47: Utilities | AH47: 200 | AI47: 200 | AJ47: 200 | AK47: 200 | AL47: 200 | AM47: 1500 | AN47: 1500 | AO47: 1500 | AP47: 1500 | AQ47: 1500 | AR47: 1500 | AS47: 1500 | AT47: 1500 | AU47: 1500 | AV47: 1500 | AW47: 1500 | AX47: 1500 | AY47: 1500 | AZ47: 1500 | BA47: 1500 | BB47: 1500 | BC47: 1500 | BD47: 1500 | BE47: 1500 | BF47: 1500 | BG47: 1500 | BH47: 1500 | BI47: 1500 | BJ47: 1500 | BK47: 1500 | BL47: 1500 | BM47: 1500 | BN47: 1500 | BO47: 1500 | BP47: 3000 | BQ47: 3000 | BR47: 3000 | BS47: 3000 | BT47: 3000 | BU47: 3000 | BV47: 3000 | BW47: 3000 | BX47: 3000 | BY47: 3000 | BZ47: 3000 | CA47: 3000 | CB47: 3000 | CC47: 3000 | CD47: 3000 | CE47: 3000 | CF47: 3000 | CG47: 3000 | CH47: 3000 | CI47: 3000 | CJ47: 3000 | CK47: 3000 | CL47: 3000 | CM47: 3000 | CN47: 3000 | CO47: 3000 | CP47: 3000
A48: Internet, cable and phone | AH48: 400 | AI48: 400 | AJ48: 400 | AK48: 400 | AL48: 400 | AM48: 800 | AN48: 800 | AO48: 800 | AP48: 800 | AQ48: 800 | AR48: 800 | AS48: 800 | AT48: 800 | AU48: 800 | AV48: 800 | AW48: 800 | AX48: 800 | AY48: 800 | AZ48: 800 | BA48: 800 | BB48: 800 | BC48: 800 | BD48: 800 | BE48: 800 | BF48: 800 | BG48: 1400 | BH48: 1400 | BI48: 1400 | BJ48: 1400 | BK48: 1400 | BL48: 1400 | BM48: 1400 | BN48: 1400 | BO48: 1400 | BP48: 1400 | BQ48: 1400 | BR48: 1400 | BS48: 1400 | BT48: 1400 | BU48: 1400 | BV48: 1400 | BW48: 1400 | BX48: 1400 | BY48: 1400 | BZ48: 1400 | CA48: 1400 | CB48: 1400 | CC48: 1400 | CD48: 1400 | CE48: 1400 | CF48: 1400 | CG48: 1400 | CH48: 1400 | CI48: 1400 | CJ48: 1400 | CK48: 1400 | CL48: 1400 | CM48: 1400 | CN48: 1400 | CO48: 1400 | CP48: 1400
A49: Computer | AH49: 500 | AI49: 500 | AJ49: 500 | AK49: 500 | AL49: 500 | AM49: 500 | AN49: 500 | AO49: 500 | AP49: 500 | AQ49: 500 | AR49: 500 | AS49: 500 | AT49: 500 | AU49: 500 | AV49: 500 | AW49: 500 | AX49: 500 | AY49: 500 | AZ49: 500 | BA49: 500 | BB49: 500 | BC49: 500 | BD49: 500 | BE49: 500 | BF49: 500 | BG49: 500 | BH49: 500 | BI49: 500 | BJ49: 500 | BK49: 500 | BL49: 500 | BM49: 500 | BN49: 500 | BO49: 500 | BP49: 500 | BQ49: 2500 | BR49: 2500 | BS49: 2500 | BT49: 2500 | BU49: 2500 | BV49: 2500 | BW49: 2500 | BX49: 2500 | BY49: 2500 | BZ49: 2500 | CA49: 2500 | CB49: 2500 | CC49: 2500 | CD49: 2500 | CE49: 2500 | CF49: 2500 | CG49: 2500 | CH49: 2500 | CI49: 2500 | CJ49: 2500 | CK49: 2500 | CL49: 2500 | CM49: 2500 | CN49: 2500 | CO49: 2500 | CP49: 2500
A50: Insurance | AH50: ='P&L Cash Flow Monthly'!AH15*0.00285 -> 256.07022 | AI50: ='P&L Cash Flow Monthly'!AI15*0.00285 -> 221.83802 | AJ50: ='P&L Cash Flow Monthly'!AJ15*0.00285 -> 200.47473 | AK50: ='P&L Cash Flow Monthly'!AK15*0.00285 -> 177.35704 | AL50: ='P&L Cash Flow Monthly'!AL15*0.00285 -> 154.73413 | AM50: ='P&L Cash Flow Monthly'!AM15*0.00285 -> 158.68567 | AN50: ='P&L Cash Flow Monthly'!AN15*0.00285 -> 164.15017 | AO50: ='P&L Cash Flow Monthly'!AO15*0.00285 -> 169.62184 | ... CP50: ='P&L Cash Flow Monthly'!CP15*0.00285 -> 718.24382
