Workbook

Sheet Explaination
B2: Basis for the cashforecast are as follows
B4: Customer Acquisition Cost (CAC)
C5: Current: $22.00 | M5: Refer to Task B file
C6: Projections: The company conservatively models CAC increasing as spend scales ($30 in Yr 1, up to $45 by Yr 4). | M6: Refer to C1 investor presentation file
B8: Revenue & Profitability
C9: First-Year Revenue: Customers are expected to spend $100 in their first year. | M9: Refer to Task B file
C10: Gross Margin: The current retail price is $4.80 per bar with a production cost of $2.20, representing a healthy margin that is expected to improve with co-packer efficiencies. | M10: Refer to Task B file
C11: Lifetime Value (LTV): The current LTV is calculated over a 3-year period of sales. | M11: Refer to C1 investor presentation file
B13: Marketing Strategy & Efficiency
C14: Efficiency: Marketing spend is targeted to average 15–16% of total revenue. | M14: Refer to C1 investor presentation file
C15: Channels: Primary focus is on paid digital (Meta, Google, TikTok) and a robust influencer network of over 120 ambassadors with a reach of 1.5M followers. | M15: Refer to C1 investor presentation file
C16: Retention: 40% of customers currently re-order within 30 days, which significantly drives down the long-term effective CAC. | M16: Refer to C1 investor presentation file
B18: Payback Period Calculation
C19: To show the lender the "ability to repay," you can highlight that the cost to acquire a customer ($22) is recovered multiple times over within the first year of that customer's relationship, as they generate approximately $60.00 in gross profit ($100 revenue × 60% margin) in Year 1 alone. | M19: Refer to C1 investor presentation file
B21: To be "lender-ready," it is crucial to show how your raw data translates into the metrics provided in the summary. Below are the detailed calculation steps based on the current performance and future projections found in the C1 Investor Presentation.
B23: Customer Acquisition Cost (CAC)
C24: Formula: Total Marketing Spend / Total New Customers
C25: Current Data: The presentation explicitly states the current CAC is $22.00.
C26: Projected Step-by-Step: For Year 1 projections, the total marketing spend for new customers is $450,000, and the expected number of new customers is 15,000.
C27: $450,000 ÷ 15,000 = $30.00 CAC (Projected Year 1). | M27: Refer to C1 investor presentation file
B29: Average First-Year Revenue Per Customer
C30: Formula: Total Revenue from New Customers / Number of New Customers
C31: Projected Step-by-Step: The presentation projects Year 1 customer spend to be $100.00.
C32: This is expected to grow as expected and reaching a projected $150.00 by Year 2. | M32: Refer to C1 investor presentation file
B34: Gross Margin Percentage
C35: Formula: ((Revenue - Cost of Goods Sold) / Revenue) x 100 | H35: Calculation
C36: Current Product Level: * Retail Price: $4.80. | H36: ='P&L Cash Flow Annual'!D17/'P&L Cash Flow Annual'!D15 -> 0.70016711 | I36: ='P&L Cash Flow Annual'!E17/'P&L Cash Flow Annual'!E15 -> 0.69052346 | J36: ='P&L Cash Flow Annual'!F17/'P&L Cash Flow Annual'!F15 -> 0.63437342 | K36: =(H36+I36+J36)/3 -> 0.67502133
C37: Cost to Produce (COGS): $2.20.
C38: Calculation: (($4.80 - $2.20) / $4.80) = 54.2%.
C39: Company-Wide Projection: The financial table shows a current company COGS of 40% (meaning a 60% margin).
C40: Target: Management expects margins to stabilize at ~67.50% from Year 2 onward due to co-packer efficiencies. | M40: Refer to C1 investor presentation file
B42: Approximate Payback Period
C43: Formula: CAC / (First-Year Revenue x Gross Margin %)
C44: Calculation:
C45: CAC: $22.00.
C46: First-Year Gross Profit: $100.00 Revenue x 60% Margin = $60.00 profit.
C47: Calculation: $22.00 / $60.00 = 0.36 years.
C48: Result: ~4.3 months to earn back the cost of acquiring the customer.
C49: Note: Using the conservative Year 1 projection ($30 CAC / $60 Profit), the payback is 6 months.
B51: Historical Return on Ad Spend (ROAS)
...

Sheet P&L Cash Flow Annual
A2: CONDITION ONE NUTRITION
A3: Cash Flow Annual
D7: Actual | E7: Actual | F7: Actual | G7: Conservative Case | I7: Base Case | K7: Optimistic Case
B8: 2021 | C8: 2022 | D8: 2023 | E8: 2024 | F8: 2025 | G8: 2026 | H8: 2027 | I8: 2026 | J8: 2027 | K8: 2026 | L8: 2027
A10: Sales
A11: Gyms | B11: =SUM('P&L Cash Flow Monthly'!K11:V11) -> 133087.11 | C11: =+'P&L Cash Flow Monthly'!W11+'P&L Cash Flow Monthly'!X11+'P&L Cash Flow Monthly'!Y11+'P&L Cash Flow Monthly'!Z11+'P&L Cash Flow Monthly'!AA11+'P&L Cash Flow Monthly'!AB11+'P&L Cash Flow Monthly'!AC11+'P&L Cash Flow Monthly'!AD11+'P&L Cash Flow Monthly'!AE11+'P&L Cash Flow Monthly'!AF11+'P&L Cash Flow Monthly'!AG11+'P&L Cash Flow Monthly'!AH11 -> 127294.62 | D11: =+'P&L Cash Flow Monthly'!AI11+'P&L Cash Flow Monthly'!AJ11+'P&L Cash Flow Monthly'!AK11+'P&L Cash Flow Monthly'!AL11+'P&L Cash Flow Monthly'!AM11+'P&L Cash Flow Monthly'!AN11+'P&L Cash Flow Monthly'!AO11+'P&L Cash Flow Monthly'!AP11+'P&L Cash Flow Monthly'!AQ11+'P&L Cash Flow Monthly'!AR11+'P&L Cash Flow Monthly'!AS11+'P&L Cash Flow Monthly'!AT11 -> 90473.632 | E11: =+'P&L Cash Flow Monthly'!AU11+'P&L Cash Flow Monthly'!AV11+'P&L Cash Flow Monthly'!AW11+'P&L Cash Flow Monthly'!AX11+'P&L Cash Flow Monthly'!AY11+'P&L Cash Flow Monthly'!AZ11+'P&L Cash Flow Monthly'!BA11+'P&L Cash Flow Monthly'!BB11+'P&L Cash Flow Monthly'!BC11+'P&L Cash Flow Monthly'!BD11+'P&L Cash Flow Monthly'!BE11+'P&L Cash Flow Monthly'!BF11 -> 132743.05 | F11: =+'P&L Cash Flow Monthly'!BG11+'P&L Cash Flow Monthly'!BH11+'P&L Cash Flow Monthly'!BI11+'P&L Cash Flow Monthly'!BJ11+'P&L Cash Flow Monthly'!BK11+'P&L Cash Flow Monthly'!BL11+'P&L Cash Flow Monthly'!BM11+'P&L Cash Flow Monthly'!BN11+'P&L Cash Flow Monthly'!BO11+'P&L Cash Flow Monthly'!BP11+'P&L Cash Flow Monthly'!BQ11+'P&L Cash Flow Monthly'!BR11 -> 128606.49 | G11: =SUM('P&L Cash Flow Monthly'!BS11:CD11) -> 201224.06 | H11: =SUM('P&L Cash Flow Monthly'!CE11:CP11) -> 317836.39 | I11: =SUM('P&L Cash Flow Monthly'!BU11:CF11) -> 220357.86 | J11: =SUM('P&L Cash Flow Monthly'!CG11:CR11) -> 275043.54 | K11: =SUM('P&L Cash Flow Monthly'!BW11:CH11) -> 239899.73 | L11: =SUM('P&L Cash Flow Monthly'!CI11:CT11) -> 228638.96
A12: E-commerce | B12: =SUM('P&L Cash Flow Monthly'!K12:V12) -> 910216.47 | C12: =+'P&L Cash Flow Monthly'!W12+'P&L Cash Flow Monthly'!X12+'P&L Cash Flow Monthly'!Y12+'P&L Cash Flow Monthly'!Z12+'P&L Cash Flow Monthly'!AA12+'P&L Cash Flow Monthly'!AB12+'P&L Cash Flow Monthly'!AC12+'P&L Cash Flow Monthly'!AD12+'P&L Cash Flow Monthly'!AE12+'P&L Cash Flow Monthly'!AF12+'P&L Cash Flow Monthly'!AG12+'P&L Cash Flow Monthly'!AH12 -> 891020.34 | D12: =+'P&L Cash Flow Monthly'!AI12+'P&L Cash Flow Monthly'!AJ12+'P&L Cash Flow Monthly'!AK12+'P&L Cash Flow Monthly'!AL12+'P&L Cash Flow Monthly'!AM12+'P&L Cash Flow Monthly'!AN12+'P&L Cash Flow Monthly'!AO12+'P&L Cash Flow Monthly'!AP12+'P&L Cash Flow Monthly'!AQ12+'P&L Cash Flow Monthly'!AR12+'P&L Cash Flow Monthly'!AS12+'P&L Cash Flow Monthly'!AT12 -> 633273.42 | E12: =+'P&L Cash Flow Monthly'!AU12+'P&L Cash Flow Monthly'!AV12+'P&L Cash Flow Monthly'!AW12+'P&L Cash Flow Monthly'!AX12+'P&L Cash Flow Monthly'!AY12+'P&L Cash Flow Monthly'!AZ12+'P&L Cash Flow Monthly'!BA12+'P&L Cash Flow Monthly'!BB12+'P&L Cash Flow Monthly'!BC12+'P&L Cash Flow Monthly'!BD12+'P&L Cash Flow Monthly'!BE12+'P&L Cash Flow Monthly'!BF12 -> 929159.32 | F12: =+'P&L Cash Flow Monthly'!BG12+'P&L Cash Flow Monthly'!BH12+'P&L Cash Flow Monthly'!BI12+'P&L Cash Flow Monthly'!BJ12+'P&L Cash Flow Monthly'!BK12+'P&L Cash Flow Monthly'!BL12+'P&L Cash Flow Monthly'!BM12+'P&L Cash Flow Monthly'!BN12+'P&L Cash Flow Monthly'!BO12+'P&L Cash Flow Monthly'!BP12+'P&L Cash Flow Monthly'!BQ12+'P&L Cash Flow Monthly'!BR12 -> 900203.45 | G12: =SUM('P&L Cash Flow Monthly'!BS12:CD12) -> 1408526.4 | H12: =SUM('P&L Cash Flow Monthly'!CE12:CP12) -> 2224812.7 | I12: =SUM('P&L Cash Flow Monthly'!BU12:CF12) -> 1542463 | J12: =SUM('P&L Cash Flow Monthly'!CG12:CR12) -> 1925269.8 | K12: =SUM('P&L Cash Flow Monthly'!BW12:CH12) -> 1679256.1 | L12: =SUM('P&L Cash Flow Monthly'!CI12:CT12) -> 1600444.7
A15: Sales | B15: =SUM(B11:B12) -> 1043303.6 | C15: =SUM(C11:C12) -> 1018315 | D15: ='P&L 2023'!N10 -> 698520.16 | E15: ='P&L 2024'!N10 -> 1014224.7 | F15: ='P&L 2025'!K13 -> 981978.58 | G15: ='Forecast P&L 2026 1'!N11 -> 1380067.3 | H15: ='Forecast P&L 2027 1'!N11 -> 1904492.9 | I15: ='Forecast P&L 2026 2'!N11 -> 1532639.7 | J15: ='Forecast P&L 2027 2'!N11 -> 2145695.5 | K15: ='Forecast P&L 2026 3'!N11 -> 1717102.9 | L15: ='Forecast P&L 2027 3'!N11 -> 2558483.4
A17: Cost of goods sold | B17: =SUM('P&L Cash Flow Monthly'!K17:V17) -> 748803.02 | C17: =+'P&L Cash Flow Monthly'!W17+'P&L Cash Flow Monthly'!X17+'P&L Cash Flow Monthly'!Y17+'P&L Cash Flow Monthly'!Z17+'P&L Cash Flow Monthly'!AA17+'P&L Cash Flow Monthly'!AB17+'P&L Cash Flow Monthly'!AC17+'P&L Cash Flow Monthly'!AD17+'P&L Cash Flow Monthly'!AE17+'P&L Cash Flow Monthly'!AF17+'P&L Cash Flow Monthly'!AG17+'P&L Cash Flow Monthly'!AH17 -> 716210.63 | D17: ='P&L 2023'!N15 -> 489080.84 | E17: ='P&L 2024'!N16 -> 700345.97 | F17: ='P&L 2025'!K18 -> 622941.11 | G17: ='Forecast P&L 2026 1'!N16 -> 938445.78 | H17: ='Forecast P&L 2027 1'!N16 -> 1295055.2 | I17: ='Forecast P&L 2026 2'!N16 -> 1042195 | J17: ='Forecast P&L 2027 2'!N16 -> 1459072.9 | K17: ='Forecast P&L 2026 3'!N16 -> 1167630 | L17: ='Forecast P&L 2027 3'!N16 -> 1739768.7
A19: Gross margin | B19: =+B15-B17 -> 294500.56 | C19: =+C15-C17 -> 302104.32 | D19: =+D15-D17 -> 209439.32 | E19: =+E15-E17 -> 313878.76 | F19: =+F15-F17 -> 359037.47 | G19: =+G15-G17 -> 441621.55 | H19: =+H15-H17 -> 609437.73 | I19: =+I15-I17 -> 490444.69 | ... L19: =+L15-L17 -> 818714.68
A21: Expenses (see tab for detail) | B21: =SUM('P&L Cash Flow Monthly'!K21:V21) -> 654881.9 | C21: =+'P&L Cash Flow Monthly'!W21+'P&L Cash Flow Monthly'!X21+'P&L Cash Flow Monthly'!Y21+'P&L Cash Flow Monthly'!Z21+'P&L Cash Flow Monthly'!AA21+'P&L Cash Flow Monthly'!AB21+'P&L Cash Flow Monthly'!AC21+'P&L Cash Flow Monthly'!AD21+'P&L Cash Flow Monthly'!AE21+'P&L Cash Flow Monthly'!AF21+'P&L Cash Flow Monthly'!AG21+'P&L Cash Flow Monthly'!AH21 -> 648488.75 | D21: ='P&L 2023'!N41 -> 279238.33 | E21: ='P&L 2024'!N45+'P&L 2024'!N49 -> 572532.29 | F21: ='P&L 2025'!K54 -> 426312.62 | G21: ='Forecast P&L 2026 1'!N52 -> 722412.12 | H21: ='Forecast P&L 2027 1'!N52 -> 816808.72 | I21: ='Forecast P&L 2026 2'!N52 -> 749875.14 | J21: ='Forecast P&L 2027 2'!N52 -> 852428.4 | K21: ='Forecast P&L 2026 3'!N52 -> 783078.53 | L21: ='Forecast P&L 2027 3'!N52 -> 934527.01
A23: Net income/EBITDA | B23: =+B19-B21 -> -360381.34 | C23: =+C19-C21 -> -346384.42 | D23: =+D19-D21 -> -69799.01 | E23: =+E19-E21 -> -258653.53 | F23: =+F19-F21 -> -67275.15 | G23: =+G19-G21 -> -280790.57 | H23: =+H19-H21 -> -207370.99 | I23: =+I19-I21 -> -259430.45 | ... L23: =+L19-L21 -> -115812.33
A25: Adjustments to convert net income to cash flow
A26: COGS | B26: =SUM('P&L Cash Flow Monthly'!K26:V26) -> 748803.02 | C26: =+'P&L Cash Flow Monthly'!W26+'P&L Cash Flow Monthly'!X26+'P&L Cash Flow Monthly'!Y26+'P&L Cash Flow Monthly'!Z26+'P&L Cash Flow Monthly'!AA26+'P&L Cash Flow Monthly'!AB26+'P&L Cash Flow Monthly'!AC26+'P&L Cash Flow Monthly'!AD26+'P&L Cash Flow Monthly'!AE26+'P&L Cash Flow Monthly'!AF26+'P&L Cash Flow Monthly'!AG26+'P&L Cash Flow Monthly'!AH26 -> 716210.63 | D26: ='P&L 2023'!N15 -> 489080.84 | E26: ='P&L 2024'!N16 -> 700345.97 | F26: ='P&L 2025'!K18 -> 622941.11 | G26: ='Forecast P&L 2026 1'!N16 -> 938445.78 | H26: ='Forecast P&L 2027 1'!N16 -> 1295055.2 | I26: ='Forecast P&L 2026 2'!N16 -> 1042195 | J26: ='Forecast P&L 2027 2'!N16 -> 1459072.9 | K26: ='Forecast P&L 2026 3'!N16 -> 1167630 | L26: ='Forecast P&L 2027 3'!N16 -> 1739768.7
A27: Payment for COGS | B27: =SUM('P&L Cash Flow Monthly'!K27:V27) -> -773403.12 | C27: =+'P&L Cash Flow Monthly'!W27+'P&L Cash Flow Monthly'!X27+'P&L Cash Flow Monthly'!Y27+'P&L Cash Flow Monthly'!Z27+'P&L Cash Flow Monthly'!AA27+'P&L Cash Flow Monthly'!AB27+'P&L Cash Flow Monthly'!AC27+'P&L Cash Flow Monthly'!AD27+'P&L Cash Flow Monthly'!AE27+'P&L Cash Flow Monthly'!AF27+'P&L Cash Flow Monthly'!AG27+'P&L Cash Flow Monthly'!AH27 -> -695924.67 | D27: =-'P&L 2023'!N15 -> -489080.84 | E27: =-'P&L 2024'!N16 -> -700345.97 | F27: =-'P&L 2025'!K18 -> -622941.11 | G27: =-'Forecast P&L 2026 1'!N16 -> -938445.78 | H27: =-'Forecast P&L 2027 1'!N16 -> -1295055.2 | I27: =-I26 -> -1042195 | J27: =-J26 -> -1459072.9 | K27: =-K26 -> -1167630 | L27: =-L26 -> -1739768.7
A28: Marketing ad spend | B28: =SUM('P&L Cash Flow Monthly'!K28:V28) -> 175000 | C28: =+'P&L Cash Flow Monthly'!W28+'P&L Cash Flow Monthly'!X28+'P&L Cash Flow Monthly'!Y28+'P&L Cash Flow Monthly'!Z28+'P&L Cash Flow Monthly'!AA28+'P&L Cash Flow Monthly'!AB28+'P&L Cash Flow Monthly'!AC28+'P&L Cash Flow Monthly'!AD28+'P&L Cash Flow Monthly'!AE28+'P&L Cash Flow Monthly'!AF28+'P&L Cash Flow Monthly'!AG28+'P&L Cash Flow Monthly'!AH28 -> 118000 | D28: ='P&L 2023'!N18 -> 112474.76 | E28: ='P&L 2024'!N19 -> 241812.9 | F28: ='P&L 2025'!K21+'P&L 2025'!K35 -> 137771.55 | G28: ='Forecast P&L 2026 1'!N33 -> 248412.12 | H28: ='Forecast P&L 2027 1'!N33 -> 342808.72 | I28: ='Forecast P&L 2026 2'!N33 -> 275875.14 | J28: ='Forecast P&L 2027 2'!N33 -> 378428.4 | K28: ='Forecast P&L 2026 3'!N33 -> 309078.53 | L28: ='Forecast P&L 2027 3'!N33 -> 460527.01
A29: Payment for Marketing ad spend | B29: =SUM('P&L Cash Flow Monthly'!K29:V29) -> -170000 | C29: =+'P&L Cash Flow Monthly'!W29+'P&L Cash Flow Monthly'!X29+'P&L Cash Flow Monthly'!Y29+'P&L Cash Flow Monthly'!Z29+'P&L Cash Flow Monthly'!AA29+'P&L Cash Flow Monthly'!AB29+'P&L Cash Flow Monthly'!AC29+'P&L Cash Flow Monthly'!AD29+'P&L Cash Flow Monthly'!AE29+'P&L Cash Flow Monthly'!AF29+'P&L Cash Flow Monthly'!AG29+'P&L Cash Flow Monthly'!AH29 -> -118000 | D29: =-'P&L 2023'!N18 -> -112474.76 | E29: =-'P&L 2024'!N19 -> -241812.9 | F29: =-'P&L 2025'!K21-'P&L 2025'!K35 -> -137771.55 | G29: =-'Forecast P&L 2026 1'!N33 -> -248412.12 | H29: =-'Forecast P&L 2027 1'!N33 -> -342808.72 | I29: =-I28 -> -275875.14 | J29: =-J28 -> -378428.4 | K29: =-K28 -> -309078.53 | L29: =-L28 -> -460527.01
A30: Initial up front costs | B30: =SUM('P&L Cash Flow Monthly'!K30:V30) -> 0 | C30: =+'P&L Cash Flow Monthly'!W30+'P&L Cash Flow Monthly'!X30+'P&L Cash Flow Monthly'!Y30+'P&L Cash Flow Monthly'!Z30+'P&L Cash Flow Monthly'!AA30+'P&L Cash Flow Monthly'!AB30+'P&L Cash Flow Monthly'!AC30+'P&L Cash Flow Monthly'!AD30+'P&L Cash Flow Monthly'!AE30+'P&L Cash Flow Monthly'!AF30+'P&L Cash Flow Monthly'!AG30+'P&L Cash Flow Monthly'!AH30 -> 0 | D30: =+'P&L Cash Flow Monthly'!AI30+'P&L Cash Flow Monthly'!AJ30+'P&L Cash Flow Monthly'!AK30+'P&L Cash Flow Monthly'!AL30+'P&L Cash Flow Monthly'!AM30+'P&L Cash Flow Monthly'!AN30+'P&L Cash Flow Monthly'!AO30+'P&L Cash Flow Monthly'!AP30+'P&L Cash Flow Monthly'!AQ30+'P&L Cash Flow Monthly'!AR30+'P&L Cash Flow Monthly'!AS30+'P&L Cash Flow Monthly'!AT30 -> 0 | E30: =+'P&L Cash Flow Monthly'!AU30+'P&L Cash Flow Monthly'!AV30+'P&L Cash Flow Monthly'!AW30+'P&L Cash Flow Monthly'!AX30+'P&L Cash Flow Monthly'!AY30+'P&L Cash Flow Monthly'!AZ30+'P&L Cash Flow Monthly'!BA30+'P&L Cash Flow Monthly'!BB30+'P&L Cash Flow Monthly'!BC30+'P&L Cash Flow Monthly'!BD30+'P&L Cash Flow Monthly'!BE30+'P&L Cash Flow Monthly'!BF30 -> 0 | F30: =+'P&L Cash Flow Monthly'!BG30+'P&L Cash Flow Monthly'!BH30+'P&L Cash Flow Monthly'!BI30+'P&L Cash Flow Monthly'!BJ30+'P&L Cash Flow Monthly'!BK30+'P&L Cash Flow Monthly'!BL30+'P&L Cash Flow Monthly'!BM30+'P&L Cash Flow Monthly'!BN30+'P&L Cash Flow Monthly'!BO30+'P&L Cash Flow Monthly'!BP30+'P&L Cash Flow Monthly'!BQ30+'P&L Cash Flow Monthly'!BR30 -> 0 | G30: =SUM('P&L Cash Flow Monthly'!BS30:CD30) -> 0 | H30: =SUM('P&L Cash Flow Monthly'!CE30:CP30) -> 0 | I30: =SUM('P&L Cash Flow Monthly'!BU30:CF30) -> 0 | J30: =SUM('P&L Cash Flow Monthly'!CG30:CR30) -> 0 | K30: =SUM('P&L Cash Flow Monthly'!BW30:CH30) -> 0 | L30: =SUM('P&L Cash Flow Monthly'!CI30:CT30) -> 0
A31: Tax distribution | B31: =SUM('P&L Cash Flow Monthly'!K31:V31) -> 0 | C31: =+'P&L Cash Flow Monthly'!W31+'P&L Cash Flow Monthly'!X31+'P&L Cash Flow Monthly'!Y31+'P&L Cash Flow Monthly'!Z31+'P&L Cash Flow Monthly'!AA31+'P&L Cash Flow Monthly'!AB31+'P&L Cash Flow Monthly'!AC31+'P&L Cash Flow Monthly'!AD31+'P&L Cash Flow Monthly'!AE31+'P&L Cash Flow Monthly'!AF31+'P&L Cash Flow Monthly'!AG31+'P&L Cash Flow Monthly'!AH31 -> 0 | D31: =+'P&L Cash Flow Monthly'!AI31+'P&L Cash Flow Monthly'!AJ31+'P&L Cash Flow Monthly'!AK31+'P&L Cash Flow Monthly'!AL31+'P&L Cash Flow Monthly'!AM31+'P&L Cash Flow Monthly'!AN31+'P&L Cash Flow Monthly'!AO31+'P&L Cash Flow Monthly'!AP31+'P&L Cash Flow Monthly'!AQ31+'P&L Cash Flow Monthly'!AR31+'P&L Cash Flow Monthly'!AS31+'P&L Cash Flow Monthly'!AT31 -> 0 | E31: =+'P&L Cash Flow Monthly'!AU31+'P&L Cash Flow Monthly'!AV31+'P&L Cash Flow Monthly'!AW31+'P&L Cash Flow Monthly'!AX31+'P&L Cash Flow Monthly'!AY31+'P&L Cash Flow Monthly'!AZ31+'P&L Cash Flow Monthly'!BA31+'P&L Cash Flow Monthly'!BB31+'P&L Cash Flow Monthly'!BC31+'P&L Cash Flow Monthly'!BD31+'P&L Cash Flow Monthly'!BE31+'P&L Cash Flow Monthly'!BF31 -> 0 | F31: =+'P&L Cash Flow Monthly'!BG31+'P&L Cash Flow Monthly'!BH31+'P&L Cash Flow Monthly'!BI31+'P&L Cash Flow Monthly'!BJ31+'P&L Cash Flow Monthly'!BK31+'P&L Cash Flow Monthly'!BL31+'P&L Cash Flow Monthly'!BM31+'P&L Cash Flow Monthly'!BN31+'P&L Cash Flow Monthly'!BO31+'P&L Cash Flow Monthly'!BP31+'P&L Cash Flow Monthly'!BQ31+'P&L Cash Flow Monthly'!BR31 -> 0 | G31: =SUM('P&L Cash Flow Monthly'!BS31:CD31) -> 0 | H31: =SUM('P&L Cash Flow Monthly'!CE31:CP31) -> 0 | I31: =SUM('P&L Cash Flow Monthly'!BU31:CF31) -> 0 | J31: =SUM('P&L Cash Flow Monthly'!CG31:CR31) -> 0 | K31: =SUM('P&L Cash Flow Monthly'!BW31:CH31) -> 0 | L31: =SUM('P&L Cash Flow Monthly'!CI31:CT31) -> 0
A32: Capital investment | B32: =SUM('P&L Cash Flow Monthly'!K32:V32) -> 400000 | C32: =+'P&L Cash Flow Monthly'!W32+'P&L Cash Flow Monthly'!X32+'P&L Cash Flow Monthly'!Y32+'P&L Cash Flow Monthly'!Z32+'P&L Cash Flow Monthly'!AA32+'P&L Cash Flow Monthly'!AB32+'P&L Cash Flow Monthly'!AC32+'P&L Cash Flow Monthly'!AD32+'P&L Cash Flow Monthly'!AE32+'P&L Cash Flow Monthly'!AF32+'P&L Cash Flow Monthly'!AG32+'P&L Cash Flow Monthly'!AH32 -> 285000 | D32: 0 | E32: 0 | F32: 0 | G32: 0 | H32: 0 | I32: 0 | J32: 0 | K32: 0 | L32: 0
A35: Annual cash flow | B35: =SUM(B23:B33) -> 20018.56 | C35: =SUM(C23:C33) -> -41098.458 | D35: =SUM(D23:D33) -> -69799.01 | E35: =SUM(E23:E33) -> -258653.53 | F35: =SUM(F23:F33) -> -67275.15 | G35: =SUM(G23:G33) -> -280790.57 | H35: =SUM(H23:H33) -> -207370.99 | I35: =SUM(I23:I33) -> -259430.45 | ... L35: =SUM(L23:L33) -> -115812.33
A37: Cash beginning of year | B37: ='P&L Cash Flow Monthly'!K37:K38 -> 179360.01 | C37: =+B39 -> 199378.57 | D37: =+C39 -> 158280.11 | E37: =+D39 -> 88481.099 | F37: =+E39 -> -170172.43 | G37: =+F39 -> -237447.58 | H37: =+G39 -> -518238.16 | I37: =F39 -> -237447.58 | J37: =+I39 -> -496878.03 | K37: =F39 -> -237447.58 | L37: =+K39 -> -471053.17
A39: Cash end of year | B39: =SUM(B35:B37) -> 199378.57 | C39: =SUM(C35:C37) -> 158280.11 | D39: =SUM(D35:D37) -> 88481.099 | E39: =SUM(E35:E37) -> -170172.43 | F39: =SUM(F35:F37) -> -237447.58 | G39: =SUM(G35:G37) -> -518238.16 | H39: =SUM(H35:H37) -> -725609.15 | I39: =SUM(I35:I37) -> -496878.03 | ... L39: =SUM(L35:L37) -> -586865.5
A42: Gross Profit % | B42: =B19/B15 -> 0.28227695 | C42: =C19/C15 -> 0.29667081 | D42: =D19/D15 -> 0.29983289 | E42: =E19/E15 -> 0.30947654 | F42: =F19/F15 -> 0.36562658 | G42: =G19/G15 -> 0.32 | H42: =H19/H15 -> 0.32 | I42: =I19/I15 -> 0.32 | ... L42: =L19/L15 -> 0.32
A44: Net Profit % | B44: =B23/B15 -> -0.34542328 | C44: =C23/C15 -> -0.34015451 | D44: =D23/D15 -> -0.099924117 | E44: =E23/E15 -> -0.25502586 | F44: =F23/F15 -> -0.068509794 | G44: =G23/G15 -> -0.2034615 | H44: =H23/H15 -> -0.10888515 | I44: =I23/I15 -> -0.16927035 | ... L44: =L23/L15 -> -0.045266008

Sheet P&L 2023
A1: Profit and Loss
A2: CONDITION ONE NUTRITION
A3: January-December, 2023
A5: Distribution account | B5: January 2023 | C5: February 2023 | D5: March 2023 | E5: April 2023 | F5: May 2023 | G5: June 2023 | H5: July 2023 | I5: August 2023 | J5: September 2023 | K5: October 2023 | L5: November 2023 | M5: December 2023 | N5: Total
A6: Income
A7: ECOMM Shopify Sales | B7: 38494.09 | C7: 38975.46 | D7: 40272.08 | E7: 39289.76 | F7: 45363.98 | G7: 37019.49 | H7: 33126.59 | I7: 34208.34 | J7: 34963.64 | K7: 39857.42 | L7: 31189.46 | M7: 25844.71 | N7: =B7+C7+D7+E7+F7+G7+H7+I7+J7+K7+L7+M7 -> 438605.02
A8: ECOMM Stripe Sales | B8: 13274.09 | C8: 12506.95 | D8: 12325.37 | E8: 11750.9 | F8: 12206.23 | G8: 22275.27 | H8: 10778.6 | I8: 10212.1 | J8: 8828.2 | K8: 10980.48 | L8: 8961.04 | M8: 8397.83 | N8: =B8+C8+D8+E8+F8+G8+H8+I8+J8+K8+L8+M8 -> 142497.06
A9: Sales of Product Income | B9: 12881.98 | C9: 10976.16 | D9: 17053.45 | E9: 9871.58 | F9: 11461.91 | G9: 9255.24 | H9: 7947.77 | I9: 11218.93 | J9: 8514.89 | K9: 7229.84 | L9: 5731.43 | M9: 5274.9 | N9: =B9+C9+D9+E9+F9+G9+H9+I9+J9+K9+L9+M9 -> 117418.08
A10: Total for Income | B10: =B7+B8+B9 -> 64650.16 | C10: =C7+C8+C9 -> 62458.57 | D10: =D7+D8+D9 -> 69650.9 | E10: =E7+E8+E9 -> 60912.24 | F10: =F7+F8+F9 -> 69032.12 | G10: =G7+G8+G9 -> 68550 | H10: =H7+H8+H9 -> 51852.96 | I10: =I7+I8+I9 -> 55639.37 | ... M10: =M7+M8+M9 -> 39517.44 | N10: =B10+C10+D10+E10+F10+G10+H10+I10+J10+K10+L10+M10 -> 698520.16
A11: Cost of Goods Sold
A12: Cost of Goods Sold | B12: 9830.06 | C12: 4846.43 | D12: 6421.92 | E12: 5062.07 | F12: 9072.82 | G12: 21527.56 | H12: 3192.68 | I12: 6884.36 | J12: 6525.22 | K12: 4673.06 | L12: 6165.75 | M12: 3400.01 | N12: =B12+C12+D12+E12+F12+G12+H12+I12+J12+K12+L12+M12 -> 87601.94
A13: Cost of labor - COS | B13: 21313.32 | C13: 19655.04 | D13: 29025.69 | E13: 22415.16 | F13: 37154.41 | G13: 20582.67 | H13: 27827.68 | I13: 15103.16 | J13: 22847.3 | K13: 29059.41 | L13: 13292.4 | M13: 22140.3 | N13: =B13+C13+D13+E13+F13+G13+H13+I13+J13+K13+L13+M13 -> 280416.54
A14: Freight & Delivery | B14: 12227.15 | C14: 11168.19 | D14: 11427.15 | E14: 10447.15 | F14: 12647.15 | G14: 9997.58 | H14: 9617.58 | I14: 9292.2 | J14: 8662.58 | K14: 10589.49 | L14: 8341.68 | M14: 6644.46 | N14: =B14+C14+D14+E14+F14+G14+H14+I14+J14+K14+L14+M14 -> 121062.36
A15: Total for Cost of Goods Sold | B15: =B12+B13+B14 -> 43370.53 | C15: =C12+C13+C14 -> 35669.66 | D15: =D12+D13+D14 -> 46874.76 | E15: =E12+E13+E14 -> 37924.38 | F15: =F12+F13+F14 -> 58874.38 | G15: =G12+G13+G14 -> 52107.81 | H15: =H12+H13+H14 -> 40637.94 | I15: =I12+I13+I14 -> 31279.72 | ... M15: =M12+M13+M14 -> 32184.77 | N15: =B15+C15+D15+E15+F15+G15+H15+I15+J15+K15+L15+M15 -> 489080.84
A16: Gross Profit | B16: =B10-B15 -> 21279.63 | C16: =C10-C15 -> 26788.91 | D16: =D10-D15 -> 22776.14 | E16: =E10-E15 -> 22987.86 | F16: =F10-F15 -> 10157.74 | G16: =G10-G15 -> 16442.19 | H16: =H10-H15 -> 11215.02 | I16: =I10-I15 -> 24359.65 | ... M16: =M10-M15 -> 7332.67 | N16: =B16+C16+D16+E16+F16+G16+H16+I16+J16+K16+L16+M16 -> 209439.32
A17: Expenses
A18: Advertising | B18: 10528.67 | C18: 8399.45 | D18: 10489.99 | E18: 9517.54 | F18: 12295.44 | G18: 10471.82 | H18: 11041.51 | I18: 8400.46 | J18: 7646.38 | K18: 8822.12 | L18: 8185.99 | M18: 6675.39 | N18: =B18+C18+D18+E18+F18+G18+H18+I18+J18+K18+L18+M18 -> 112474.76
A19: Automobile Expense | B19: 134.95 | C19: 34.95 | D19: 34.95 | E19: 34.95 | F19: 41.95 | G19: 34.95 | H19: 34.95 | I19: 34.95 | J19: 168.4 | K19: 34.95 | L19: 260.51 | M19: 34.95 | N19: =B19+C19+D19+E19+F19+G19+H19+I19+J19+K19+L19+M19 -> 885.41
A20: Gas | B20: 390.44 | C20: 78.73 | D20: 655.56 | E20: 412.28 | F20: 222.22 | G20: 77.3 | H20: 488.01 | I20: 285 | J20: 210.07 | K20: 220.48 | L20: 91.58 | M20: 210.47 | N20: =B20+C20+D20+E20+F20+G20+H20+I20+J20+K20+L20+M20 -> 3342.14
A21: Parking | D21: 12 | F21: 31 | H21: 6 | K21: 12 | L21: 69.89 | N21: =B21+C21+D21+E21+F21+G21+H21+I21+J21+K21+L21+M21 -> 130.89
A22: Total for Automobile Expense | B22: =B19+B20+B21 -> 525.39 | C22: =C19+C20+C21 -> 113.68 | D22: =D19+D20+D21 -> 702.51 | E22: =E19+E20+E21 -> 447.23 | F22: =F19+F20+F21 -> 295.17 | G22: =G19+G20+G21 -> 112.25 | H22: =H19+H20+H21 -> 528.96 | I22: =I19+I20+I21 -> 319.95 | ... M22: =M19+M20+M21 -> 245.42 | N22: =B22+C22+D22+E22+F22+G22+H22+I22+J22+K22+L22+M22 -> 4358.44
A23: Bank Fees | B23: 597.22 | C23: 25 | D23: 48.33 | E23: 10.5 | F23: 5.5 | G23: 140.26 | H23: 5 | I23: 12.59 | J23: 3 | K23: 8.5 | L23: 11.5 | M23: 69.43 | N23: =B23+C23+D23+E23+F23+G23+H23+I23+J23+K23+L23+M23 -> 936.83
A24: Computer Expense | B24: 1047.15 | C24: 1047.15 | D24: 1047.15 | E24: 31.5 | F24: 31.5 | G24: 31.5 | H24: 31.5 | I24: 31.5 | J24: 31.5 | K24: 31.5 | L24: 31.5 | M24: 31.5 | N24: =B24+C24+D24+E24+F24+G24+H24+I24+J24+K24+L24+M24 -> 3424.95
A25: Entertainment | B25: 267.58 | C25: 239.57 | D25: 188.91 | E25: 121.6 | F25: 299.43 | G25: 266.44 | H25: 207.92 | I25: 207.3 | J25: 201.16 | K25: 506.11 | L25: 290.82 | M25: 254.35 | N25: =B25+C25+D25+E25+F25+G25+H25+I25+J25+K25+L25+M25 -> 3051.19
A26: Insurance | B26: 289.45 | C26: 289.45 | D26: 289.45 | E26: 289.45 | G26: 751.93 | H26: 190.3 | I26: 211.1 | J26: 195.9 | K26: 195.9 | M26: 212.21 | N26: =B26+C26+D26+E26+F26+G26+H26+I26+J26+K26+L26+M26 -> 2915.14
A27: Legal Fees | G27: -27423.93 | N27: =B27+C27+D27+E27+F27+G27+H27+I27+J27+K27+L27+M27 -> -27423.93
A28: Lodging | H28: 168.96 | I28: 410 | J28: 322.6 | L28: 203.39 | M28: 1602.73 | N28: =B28+C28+D28+E28+F28+G28+H28+I28+J28+K28+L28+M28 -> 2707.68
A29: Meals | B29: 1771.68 | C29: 492.77 | D29: 991.72 | E29: 905.42 | F29: 1701.01 | G29: 272.73 | H29: 1331.02 | I29: 1118.22 | J29: 978.5 | K29: 1180.99 | L29: 3051.54 | M29: 1505.61 | N29: =B29+C29+D29+E29+F29+G29+H29+I29+J29+K29+L29+M29 -> 15301.21
A30: Membership | B30: 315.26 | C30: 76.25 | D30: 129.66 | E30: 52.99 | F30: 670.7 | G30: 576.54 | H30: 128.66 | I30: 109.83 | J30: 153.08 | K30: 172.36 | L30: 447.91 | M30: 362.85 | N30: =B30+C30+D30+E30+F30+G30+H30+I30+J30+K30+L30+M30 -> 3196.09
A31: Merchant Fees | B31: 580.51 | C31: 497.06 | D31: 567.17 | E31: 1530.02 | F31: 1921.19 | G31: 1737.28 | H31: 1734.04 | I31: 1235.65 | J31: 1377.13 | K31: 1635.07 | L31: 1272.28 | M31: 1117.23 | N31: =B31+C31+D31+E31+F31+G31+H31+I31+J31+K31+L31+M31 -> 15204.63
A32: Miscellaneous | B32: 100 | C32: 100 | D32: 217.58 | E32: 74.6 | F32: 295.8 | H32: 322.24 | I32: 33.87 | J32: 71.48 | K32: 1273.99 | L32: 38.39 | M32: 42.18 | N32: =B32+C32+D32+E32+F32+G32+H32+I32+J32+K32+L32+M32 -> 2570.13
A33: Office Expense | B33: 1927.76 | C33: 862.69 | D33: 1223.66 | E33: 1444.2 | F33: 2878.46 | G33: 1415.34 | H33: 2803.85 | I33: 2429.02 | J33: 2922.94 | K33: 3447.64 | L33: 3161.42 | M33: 4844.87 | N33: =B33+C33+D33+E33+F33+G33+H33+I33+J33+K33+L33+M33 -> 29361.85
A34: Other General & Administrative | B34: 150.42 | E34: 27 | F34: 123.46 | G34: 568.55 | L34: 612.18 | M34: 35.33 | N34: =B34+C34+D34+E34+F34+G34+H34+I34+J34+K34+L34+M34 -> 1516.94
A35: Outside Consultants | B35: 6149.92 | C35: 3667.4 | D35: 10485.47 | E35: 6325.84 | F35: 2658.38 | G35: 5163.31 | H35: 7868.78 | I35: 6908.67 | J35: 7011.66 | K35: 5530.32 | L35: 4736.19 | M35: 4406.58 | N35: =B35+C35+D35+E35+F35+G35+H35+I35+J35+K35+L35+M35 -> 70912.52
A36: Postage | B36: 1000 | I36: 100 | L36: 100 | N36: =B36+C36+D36+E36+F36+G36+H36+I36+J36+K36+L36+M36 -> 1200
A37: Purchases | E37: 261.46 | I37: 275.92 | N37: =B37+C37+D37+E37+F37+G37+H37+I37+J37+K37+L37+M37 -> 537.38
A38: Rent | B38: 1150 | C38: 1150 | D38: 1150 | E38: 1150 | F38: 1150 | G38: 1250 | H38: 1150 | I38: 1150 | J38: 1150 | K38: 1150 | L38: 1150 | M38: 1150 | N38: =B38+C38+D38+E38+F38+G38+H38+I38+J38+K38+L38+M38 -> 13900
A39: Travel | B39: 1598.84 | C39: 264.72 | D39: 2564.48 | E39: 846.81 | F39: 970.06 | G39: 608.78 | H39: 1903.07 | I39: 2827.87 | J39: 402.41 | K39: 556.97 | L39: 3140.57 | M39: 1371.96 | N39: =B39+C39+D39+E39+F39+G39+H39+I39+J39+K39+L39+M39 -> 17056.54
A40: Uber | B40: 16.24 | C40: 55.45 | D40: 407.41 | E40: 321.31 | F40: 716.12 | G40: 691.21 | H40: 457.76 | I40: 16.24 | J40: 563.06 | K40: 852.62 | L40: 856.85 | M40: 1081.71 | N40: =B40+C40+D40+E40+F40+G40+H40+I40+J40+K40+L40+M40 -> 6035.98
A41: Total for Expenses | B41: =B18+B22+B23+B24+B25+B26+B27+B28+B29+B30+B31+B32+B33+B34+B35+B36+B37+B38+B39+B40 -> 28016.09 | C41: =C18+C22+C23+C24+C25+C26+C27+C28+C29+C30+C31+C32+C33+C34+C35+C36+C37+C38+C39+C40 -> 17280.64 | D41: =D18+D22+D23+D24+D25+D26+D27+D28+D29+D30+D31+D32+D33+D34+D35+D36+D37+D38+D39+D40 -> 30503.49 | E41: =E18+E22+E23+E24+E25+E26+E27+E28+E29+E30+E31+E32+E33+E34+E35+E36+E37+E38+E39+E40 -> 23357.47 | F41: =F18+F22+F23+F24+F25+F26+F27+F28+F29+F30+F31+F32+F33+F34+F35+F36+F37+F38+F39+F40 -> 26012.22 | G41: =G18+G22+G23+G24+G25+G26+G27+G28+G29+G30+G31+G32+G33+G34+G35+G36+G37+G38+G39+G40 -> -3365.99 | H41: =H18+H22+H23+H24+H25+H26+H27+H28+H29+H30+H31+H32+H33+H34+H35+H36+H37+H38+H39+H40 -> 29873.57 | I41: =I18+I22+I23+I24+I25+I26+I27+I28+I29+I30+I31+I32+I33+I34+I35+I36+I37+I38+I39+I40 -> 25798.19 | ... M41: =M18+M22+M23+M24+M25+M26+M27+M28+M29+M30+M31+M32+M33+M34+M35+M36+M37+M38+M39+M40 -> 25009.35 | N41: =B41+C41+D41+E41+F41+G41+H41+I41+J41+K41+L41+M41 -> 279238.33
...

Sheet P&L 2024
A1: Profit and Loss
A2: CONDITION ONE NUTRITION
A3: January-December, 2024
A5: Distribution account | B5: January 2024 | C5: February 2024 | D5: March 2024 | E5: April 2024 | F5: May 2024 | G5: June 2024 | H5: July 2024 | I5: August 2024 | J5: September 2024 | K5: October 2024 | L5: November 2024 | M5: December 2024 | N5: Total
A6: Income
A7: ECOMM PayPal Sales | B7: 6531.2 | C7: 7665.3 | D7: 12243.7 | E7: 10368.2 | F7: 10717.1 | G7: 10363.3 | H7: 13924.5 | I7: 12899.7 | J7: 12099.13 | K7: 9860.72 | L7: 14666.64 | M7: 7736.37 | N7: =B7+C7+D7+E7+F7+G7+H7+I7+J7+K7+L7+M7 -> 129075.86
A8: ECOMM Shopify Sales | B8: 36475.75 | C8: 33157.12 | D8: 50289.19 | E8: 59130.24 | F8: 61029.36 | G8: 50245.98 | H8: 76604.43 | I8: 101727.59 | J8: 74239.13 | K8: 94252.6 | L8: 89715.51 | M8: 78334.59 | N8: =B8+C8+D8+E8+F8+G8+H8+I8+J8+K8+L8+M8 -> 805201.49
A9: ECOMM Stripe Sales | B9: 6044.39 | C9: 5859.82 | D9: 6172.42 | E9: 6268.65 | F9: 6478.62 | G9: 7302.77 | H9: 6180.55 | I9: 7171.18 | J9: 7755.7 | K9: 6276.58 | L9: 9566.41 | M9: 4870.29 | N9: =B9+C9+D9+E9+F9+G9+H9+I9+J9+K9+L9+M9 -> 79947.38
A10: Total for Income | B10: =B7+B8+B9 -> 49051.34 | C10: =C7+C8+C9 -> 46682.24 | D10: =D7+D8+D9 -> 68705.31 | E10: =E7+E8+E9 -> 75767.09 | F10: =F7+F8+F9 -> 78225.08 | G10: =G7+G8+G9 -> 67912.05 | H10: =H7+H8+H9 -> 96709.48 | I10: =I7+I8+I9 -> 121798.47 | ... M10: =M7+M8+M9 -> 90941.25 | N10: =B10+C10+D10+E10+F10+G10+H10+I10+J10+K10+L10+M10 -> 1014224.7 | P10: =SUM(K10:M10) -> 315279.71
A11: Cost of Goods Sold
A12: Cost of Goods Sold | B12: 10599.06 | C12: 7570.31 | D12: 16788.95 | E12: 5196.38 | F12: 26828.8 | G12: 12294.59 | H12: 17129.39 | I12: 14817.35 | J12: 15713.13 | K12: 14554.12 | L12: 15101.89 | M12: 20698.3 | N12: =B12+C12+D12+E12+F12+G12+H12+I12+J12+K12+L12+M12 -> 177292.27
A13: Cost of labor - COS | B13: 6679.55 | C13: 14791.25 | D13: 14931.31 | E13: 26319.79 | F13: 29678.04 | G13: 9649.56 | H13: 21267.59 | I13: 41625 | J13: 38381.12 | K13: 38231.7 | L13: 22542.15 | M13: 16518.02 | N13: =B13+C13+D13+E13+F13+G13+H13+I13+J13+K13+L13+M13 -> 280615.08
A14: Freight & Delivery | B14: 9855.79 | C14: 9195.52 | D14: 14967.36 | E14: 16673.67 | F14: 13933.27 | G14: 14902.22 | H14: 20371.57 | I14: 29760.77 | J14: 17575.42 | K14: 26315.55 | L14: 19544.48 | M14: 21776.65 | N14: =B14+C14+D14+E14+F14+G14+H14+I14+J14+K14+L14+M14 -> 214872.27
A15: Supplies | B15: 693.11 | C15: 6539.95 | D15: 1589.12 | E15: 6329.32 | F15: 1692.47 | G15: 1341.67 | H15: 6822.47 | J15: 2558.24 | N15: =B15+C15+D15+E15+F15+G15+H15+I15+J15+K15+L15+M15 -> 27566.35
A16: Total for Cost of Goods Sold | B16: =B12+B13+B14+B15 -> 27827.51 | C16: =C12+C13+C14+C15 -> 38097.03 | D16: =D12+D13+D14+D15 -> 48276.74 | E16: =E12+E13+E14+E15 -> 54519.16 | F16: =F12+F13+F14+F15 -> 72132.58 | G16: =G12+G13+G14+G15 -> 38188.04 | H16: =H12+H13+H14+H15 -> 65591.02 | I16: =I12+I13+I14+I15 -> 86203.12 | ... M16: =M12+M13+M14+M15 -> 58992.97 | N16: =B16+C16+D16+E16+F16+G16+H16+I16+J16+K16+L16+M16 -> 700345.97
A17: Gross Profit | B17: =B10-B16 -> 21223.83 | C17: =C10-C16 -> 8585.21 | D17: =D10-D16 -> 20428.57 | E17: =E10-E16 -> 21247.93 | F17: =F10-F16 -> 6092.5 | G17: =G10-G16 -> 29724.01 | H17: =H10-H16 -> 31118.46 | I17: =I10-I16 -> 35595.35 | ... M17: =M10-M16 -> 31948.28 | N17: =B17+C17+D17+E17+F17+G17+H17+I17+J17+K17+L17+M17 -> 313878.76
A18: Expenses
A19: Advertising | B19: 8551.71 | C19: 14213.97 | D19: 26013.99 | E19: 27214.61 | F19: 18271.27 | G19: 21703.28 | H19: 33654.05 | I19: 26668.44 | J19: 16603.84 | K19: 15276.9 | L19: 16349.7 | M19: 17291.14 | N19: =B19+C19+D19+E19+F19+G19+H19+I19+J19+K19+L19+M19 -> 241812.9
A20: Automobile Expense | B20: 732.81 | C20: 109.94 | D20: 384.2 | E20: 225.41 | F20: 53.45 | G20: 65.95 | H20: 115.45 | I20: 34.95 | K20: 213.14 | L20: 326.37 | M20: 169.61 | N20: =B20+C20+D20+E20+F20+G20+H20+I20+J20+K20+L20+M20 -> 2431.28
A21: Gas | B21: 514.89 | C21: 300.52 | D21: 310.97 | E21: 247.49 | F21: 483.32 | G21: 376.6 | H21: 274.22 | I21: 149.86 | J21: 111.08 | K21: 788 | L21: 489.56 | M21: 332.13 | N21: =B21+C21+D21+E21+F21+G21+H21+I21+J21+K21+L21+M21 -> 4378.64
A22: Parking | B22: 46 | C22: 15 | D22: 42.05 | F22: 90.42 | G22: 10 | H22: 18 | J22: 10.99 | K22: 18.5 | L22: 40.99 | M22: 130.11 | N22: =B22+C22+D22+E22+F22+G22+H22+I22+J22+K22+L22+M22 -> 422.06
A23: Total for Automobile Expense | B23: =B20+B21+B22 -> 1293.7 | C23: =C20+C21+C22 -> 425.46 | D23: =D20+D21+D22 -> 737.22 | E23: =E20+E21+E22 -> 472.9 | F23: =F20+F21+F22 -> 627.19 | G23: =G20+G21+G22 -> 452.55 | H23: =H20+H21+H22 -> 407.67 | I23: =I20+I21+I22 -> 184.81 | ... M23: =M20+M21+M22 -> 631.85 | N23: =B23+C23+D23+E23+F23+G23+H23+I23+J23+K23+L23+M23 -> 7231.98
A24: Bank Fees | B24: 120.75 | C24: 78 | D24: 129 | E24: 800 | F24: 189.41 | G24: 270.47 | H24: 190.31 | I24: 125.85 | J24: 298.33 | K24: 542.02 | L24: 541.14 | M24: 351.37 | N24: =B24+C24+D24+E24+F24+G24+H24+I24+J24+K24+L24+M24 -> 3636.65
A25: Computer Expense | H25: 446.44 | M25: 1097.1 | N25: =B25+C25+D25+E25+F25+G25+H25+I25+J25+K25+L25+M25 -> 1543.54
A26: Entertainment | B26: 97.75 | C26: 455.06 | D26: 574.93 | E26: 538.71 | F26: 825 | G26: 451.6 | H26: 558.61 | I26: 291.63 | J26: 596.26 | K26: 320.45 | L26: 502.23 | M26: 912.17 | N26: =B26+C26+D26+E26+F26+G26+H26+I26+J26+K26+L26+M26 -> 6124.4
A27: Insurance | B27: 197.16 | C27: 197.16 | D27: 197.16 | E27: 197.16 | F27: 197.15 | G27: 212.21 | H27: 197.16 | I27: 197.16 | J27: 197.16 | K27: 197.16 | L27: 197.15 | M27: 225.21 | N27: =B27+C27+D27+E27+F27+G27+H27+I27+J27+K27+L27+M27 -> 2409
A28: Interest Expense | F28: 872.73 | N28: =B28+C28+D28+E28+F28+G28+H28+I28+J28+K28+L28+M28 -> 872.73
A29: Legal Fees | B29: 314.56 | C29: 2475.55 | D29: 567.89 | E29: 300.64 | F29: 2000 | J29: 302.42 | L29: 6878.91 | M29: 1350 | N29: =B29+C29+D29+E29+F29+G29+H29+I29+J29+K29+L29+M29 -> 14189.97
A30: Lodging | B30: 726.32 | E30: 778.51 | G30: 271.43 | J30: 1842.41 | K30: 1974.51 | L30: 220.13 | M30: 351.82 | N30: =B30+C30+D30+E30+F30+G30+H30+I30+J30+K30+L30+M30 -> 6165.13
A31: Meals | B31: 1316.46 | C31: 2111.18 | D31: 2247.95 | E31: 3053.35 | F31: 2640.27 | G31: 2741.4 | H31: 2212.51 | I31: 1678.79 | J31: 2044.36 | K31: 3038.47 | L31: 3004.16 | M31: 2681.32 | N31: =B31+C31+D31+E31+F31+G31+H31+I31+J31+K31+L31+M31 -> 28770.22
A32: Medical | C32: 7.29 | E32: 24.48 | F32: 131.03 | G32: 154.29 | I32: 49.41 | J32: 16.73 | K32: 74.39 | L32: 8.04 | N32: =B32+C32+D32+E32+F32+G32+H32+I32+J32+K32+L32+M32 -> 465.66
A33: Membership | B33: 634.31 | C33: 353.7 | D33: 357.24 | E33: 424.82 | F33: 544.24 | G33: 341.99 | H33: 581.28 | I33: 567.18 | J33: 445.66 | K33: 617.26 | L33: 376.41 | M33: 443.67 | N33: =B33+C33+D33+E33+F33+G33+H33+I33+J33+K33+L33+M33 -> 5687.76
A34: Merchant Fees | B34: 266.44 | C34: 232.57 | D34: 259.77 | E34: 256.63 | F34: 235.82 | G34: 273.39 | H34: 259.79 | I34: 272.16 | J34: 657.61 | K34: 246.13 | L34: 225.76 | M34: 279.44 | N34: =B34+C34+D34+E34+F34+G34+H34+I34+J34+K34+L34+M34 -> 3465.51
A35: Miscellaneous | C35: 1398.52 | D35: 484.94 | F35: 257.94 | G35: 640.89 | I35: 85 | K35: 732.8 | L35: 28 | M35: 284.64 | N35: =B35+C35+D35+E35+F35+G35+H35+I35+J35+K35+L35+M35 -> 3912.73
A36: Office Expense | B36: 5292.03 | C36: 1602.12 | D36: 3917.07 | E36: 7906.62 | F36: 5206.57 | G36: 3742.68 | H36: 3715.91 | I36: 4619.77 | J36: 3863.51 | K36: 5555.69 | L36: 3426.34 | M36: 2695.48 | N36: =B36+C36+D36+E36+F36+G36+H36+I36+J36+K36+L36+M36 -> 51543.79
A37: Other General & Administrative | B37: 1160.25 | C37: 1131.89 | D37: 611.29 | E37: 760.89 | F37: 810.65 | G37: 1009.51 | H37: 1058.38 | I37: 547.84 | J37: 804.93 | K37: 765.08 | L37: 785.61 | M37: 388.41 | N37: =B37+C37+D37+E37+F37+G37+H37+I37+J37+K37+L37+M37 -> 9834.73
A38: Outside Consultants | B38: 12806.9 | C38: 11616.82 | D38: 14175.45 | E38: 14118.97 | F38: 15500.81 | G38: 11481.87 | H38: 14564.08 | I38: 14855.07 | J38: 13306.16 | K38: 12193.87 | L38: 9452.45 | M38: 6462.6 | N38: =B38+C38+D38+E38+F38+G38+H38+I38+J38+K38+L38+M38 -> 150535.05
A39: Prime Video | B39: 129.17 | C39: 62.94 | D39: 62.94 | E39: 62.94 | F39: 62.94 | G39: 62.94 | H39: 88.8 | I39: 51.24 | J39: 67.43 | K39: 31.26 | L39: 151.71 | M39: 126.86 | N39: =B39+C39+D39+E39+F39+G39+H39+I39+J39+K39+L39+M39 -> 961.17
A40: Rent | B40: 1150 | C40: 1150 | D40: 1150 | E40: 1150 | F40: 1300 | G40: 1300 | H40: 1300 | I40: 1400 | J40: 1300 | K40: 1300 | L40: 1300 | M40: 1300 | N40: =B40+C40+D40+E40+F40+G40+H40+I40+J40+K40+L40+M40 -> 15100
A41: Software & Apps | B41: 319.92 | C41: 317.81 | D41: 317.81 | E41: 317.81 | F41: 317.81 | G41: 299.81 | H41: 317.81 | I41: 65.18 | J41: 320.81 | K41: 86.18 | L41: 320.81 | M41: 350.8 | N41: =B41+C41+D41+E41+F41+G41+H41+I41+J41+K41+L41+M41 -> 3352.56
...

Sheet P&L 2025
A1: Profit and Loss
A2: CONDITION ONE NUTRITION
A3: January-September, 2025
A5: Distribution account | B5: January 2025 | C5: February 2025 | D5: March 2025 | E5: April 2025 | F5: May 2025 | G5: June 2025 | H5: July 2025 | I5: August 2025 | J5: September 2025 | K5: Total
A6: Income
A7: ECOMM PayPal Sales | B7: 9846.19 | C7: 8222.59 | D7: 10931.57 | E7: 7336.88 | F7: 8746.5 | G7: 6475.07 | H7: 31376.34 | I7: 8500.4 | J7: 3691.54 | K7: =B7+C7+D7+E7+F7+G7+H7+I7+J7 -> 95127.08
A8: ECOMM Shopify Sales | B8: 78228.28 | C8: 84622.71 | D8: 85481.54 | E8: 93550.18 | F8: 90910.6 | G8: 77453.01 | H8: 81559.75 | I8: 83637.63 | J8: 77933.06 | K8: =B8+C8+D8+E8+F8+G8+H8+I8+J8 -> 753376.76
A9: ECOMM Stripe Sales | B9: 5089.66 | C9: 4564.74 | D9: 4753.17 | E9: 4315.47 | F9: 4825.21 | G9: 3739 | H9: 5864.1 | I9: 4395.99 | J9: 4902.3 | K9: =B9+C9+D9+E9+F9+G9+H9+I9+J9 -> 42449.64
A10: other income | J10: 88312.98 | K10: =B10+C10+D10+E10+F10+G10+H10+I10+J10 -> 88312.98
A11: Sales of Product Income | D11: 1000 | I11: 1887.12 | K11: =B11+C11+D11+E11+F11+G11+H11+I11+J11 -> 2887.12
A12: Sales Tax | J12: -175 | K12: =B12+C12+D12+E12+F12+G12+H12+I12+J12 -> -175
A13: Total for Income | B13: =B7+B8+B9+B10+B11+B12 -> 93164.13 | C13: =C7+C8+C9+C10+C11+C12 -> 97410.04 | D13: =D7+D8+D9+D10+D11+D12 -> 102166.28 | E13: =E7+E8+E9+E10+E11+E12 -> 105202.53 | F13: =F7+F8+F9+F10+F11+F12 -> 104482.31 | G13: =G7+G8+G9+G10+G11+G12 -> 87667.08 | H13: =H7+H8+H9+H10+H11+H12 -> 118800.19 | I13: =I7+I8+I9+I10+I11+I12 -> 98421.14 | J13: =J7+J8+J9+J10+J11+J12 -> 174664.88 | K13: =B13+C13+D13+E13+F13+G13+H13+I13+J13 -> 981978.58 | M13: 315279.71
A14: Cost of Goods Sold | M14: =K13+M13 -> 1297258.3
A15: Cost of Goods Sold | B15: 55595.51 | C15: 19437.42 | D15: 35862.31 | E15: 10195 | F15: 3190.72 | G15: 20272.18 | H15: 23157.25 | I15: 36491.43 | J15: 14859.42 | K15: =B15+C15+D15+E15+F15+G15+H15+I15+J15 -> 219061.24 | M15: 1297258.3
A16: Cost of labor - COS | B16: 13643.19 | C16: 21253.38 | D16: 18362.06 | E16: 24565.16 | F16: 25264.22 | G16: 36343.86 | H16: 35746.97 | I16: 20412.24 | J16: 33044.81 | K16: =B16+C16+D16+E16+F16+G16+H16+I16+J16 -> 228635.89
A17: Freight & Delivery | B17: 20956.85 | C17: 17755.68 | D17: 21502.45 | E17: 21331.07 | F17: 20822.5 | G17: 17028.05 | H17: 20249.71 | I17: 18782.91 | J17: 16814.76 | K17: =B17+C17+D17+E17+F17+G17+H17+I17+J17 -> 175243.98
A18: Total for Cost of Goods Sold | B18: =B15+B16+B17 -> 90195.55 | C18: =C15+C16+C17 -> 58446.48 | D18: =D15+D16+D17 -> 75726.82 | E18: =E15+E16+E17 -> 56091.23 | F18: =F15+F16+F17 -> 49277.44 | G18: =G15+G16+G17 -> 73644.09 | H18: =H15+H16+H17 -> 79153.93 | I18: =I15+I16+I17 -> 75686.58 | J18: =J15+J16+J17 -> 64718.99 | K18: =B18+C18+D18+E18+F18+G18+H18+I18+J18 -> 622941.11
A19: Gross Profit | B19: =B13-B18 -> 2968.58 | C19: =C13-C18 -> 38963.56 | D19: =D13-D18 -> 26439.46 | E19: =E13-E18 -> 49111.3 | F19: =F13-F18 -> 55204.87 | G19: =G13-G18 -> 14022.99 | H19: =H13-H18 -> 39646.26 | I19: =I13-I18 -> 22734.56 | J19: =J13-J18 -> 109945.89 | K19: =B19+C19+D19+E19+F19+G19+H19+I19+J19 -> 359037.47
A20: Expenses
A21: Advertising | B21: 3391.24 | C21: 3474.67 | D21: 3388.02 | E21: 3329.16 | F21: 3324.67 | G21: 3419.34 | H21: 3403.39 | I21: 3332.2 | J21: 2185.4 | K21: =B21+C21+D21+E21+F21+G21+H21+I21+J21 -> 29248.09
A22: Automobile Expense | B22: 333.27 | C22: 312.4 | D22: 2940.77 | E22: 198.16 | F22: 828.98 | G22: 925.81 | H22: 448.37 | I22: 70.98 | J22: 53.21 | K22: =B22+C22+D22+E22+F22+G22+H22+I22+J22 -> 6111.95
A23: Gas | B23: 145.76 | C23: 228.77 | D23: 44.8 | E23: 47.56 | F23: 57.73 | G23: 90.03 | H23: 154.73 | I23: 117.8 | J23: 143.64 | K23: =B23+C23+D23+E23+F23+G23+H23+I23+J23 -> 1030.82
A24: Parking | F24: 32.95 | G24: 5.55 | H24: 5.5 | I24: 54.9 | J24: 24.11 | K24: =B24+C24+D24+E24+F24+G24+H24+I24+J24 -> 123.01
A25: Total for Automobile Expense | B25: =B22+B23+B24 -> 479.03 | C25: =C22+C23+C24 -> 541.17 | D25: =D22+D23+D24 -> 2985.57 | E25: =E22+E23+E24 -> 245.72 | F25: =F22+F23+F24 -> 919.66 | G25: =G22+G23+G24 -> 1021.39 | H25: =H22+H23+H24 -> 608.6 | I25: =I22+I23+I24 -> 243.68 | J25: =J22+J23+J24 -> 220.96 | K25: =B25+C25+D25+E25+F25+G25+H25+I25+J25 -> 7265.78
A26: Bank Fees | B26: 350.51 | C26: 468.04 | D26: 34.34 | E26: 167.61 | F26: 132.5 | G26: 81 | H26: 123.5 | I26: 110.48 | J26: 164.79 | K26: =B26+C26+D26+E26+F26+G26+H26+I26+J26 -> 1632.77
A27: Charitable & Donations | B27: 100 | F27: 500 | K27: =B27+C27+D27+E27+F27+G27+H27+I27+J27 -> 600
A28: Computer Expense | B28: 1242.25 | C28: 1215.1 | D28: 1323.73 | K28: =B28+C28+D28+E28+F28+G28+H28+I28+J28 -> 3781.08
A29: Dues & Subscriptions | E29: 2926.52 | F29: 2930.88 | G29: 3060.02 | H29: 3460.53 | I29: 6263.39 | J29: 9870.73 | K29: =B29+C29+D29+E29+F29+G29+H29+I29+J29 -> 28512.07
A30: Entertainment | B30: 861.91 | C30: 1003.35 | D30: 794.78 | E30: 1849.72 | F30: 1259.74 | G30: 1258.36 | H30: 2105.3 | I30: -108.44 | J30: 576.72 | K30: =B30+C30+D30+E30+F30+G30+H30+I30+J30 -> 9601.44
A31: Insurance | B31: 210.16 | C31: 210.16 | D31: 210.16 | E31: 210.16 | F31: 210.15 | G31: 225.21 | H31: 459.16 | I31: 210.16 | J31: 210.16 | K31: =B31+C31+D31+E31+F31+G31+H31+I31+J31 -> 2155.48
A32: Interest Expense | F32: 113.63 | G32: 111.54 | H32: 103.77 | I32: 86.92 | J32: 109.89 | K32: =B32+C32+D32+E32+F32+G32+H32+I32+J32 -> 525.75
A33: Legal Fees | B33: 350 | C33: 2935 | D33: 2154.36 | E33: 1725 | F33: 1963.01 | H33: 0 | I33: 1485 | J33: 1382.5 | K33: =B33+C33+D33+E33+F33+G33+H33+I33+J33 -> 11994.87
A34: Lodging | C34: 996.81 | D34: 214.52 | F34: 329.98 | G34: 749.34 | H34: 883.99 | J34: 416.59 | K34: =B34+C34+D34+E34+F34+G34+H34+I34+J34 -> 3591.23
A35: Marketing | B35: 12527.64 | C35: 11451.74 | D35: 13331.05 | E35: 12428.63 | F35: 12634.9 | G35: 13097.47 | H35: 13495.17 | I35: 10945.97 | J35: 8610.89 | K35: =B35+C35+D35+E35+F35+G35+H35+I35+J35 -> 108523.46
A36: Meals | B36: 1557.66 | C36: 2154.85 | D36: 2264.46 | E36: 4565.74 | F36: 3101.83 | G36: 2601.58 | H36: 3463.33 | I36: 3155.15 | J36: 1852.36 | K36: =B36+C36+D36+E36+F36+G36+H36+I36+J36 -> 24716.96
A37: Medical | B37: 230.18 | C37: 1068.82 | D37: 200.15 | E37: 65 | F37: 54.48 | H37: 2543.15 | K37: =B37+C37+D37+E37+F37+G37+H37+I37+J37 -> 4161.78
A38: Membership | B38: 242.7 | C38: 117.52 | D38: 679.64 | E38: 1254 | F38: 247.75 | G38: 353.53 | H38: 735.43 | I38: 635 | J38: 257.74 | K38: =B38+C38+D38+E38+F38+G38+H38+I38+J38 -> 4523.31
A39: Merchant Fees | B39: 189.4 | C39: 179.53 | D39: 184.93 | E39: 267.13 | F39: 177.15 | G39: 136.4 | H39: 191.07 | K39: =B39+C39+D39+E39+F39+G39+H39+I39+J39 -> 1325.61
A40: Stripe Fee | D40: 15.06 | E40: 19.54 | F40: 37.29 | G40: 36.55 | H40: 164.98 | I40: 264.79 | J40: 162.29 | K40: =B40+C40+D40+E40+F40+G40+H40+I40+J40 -> 700.5
A41: Total for Merchant Fees | B41: =B39+B40 -> 189.4 | C41: =C39+C40 -> 179.53 | D41: =D39+D40 -> 199.99 | E41: =E39+E40 -> 286.67 | F41: =F39+F40 -> 214.44 | G41: =G39+G40 -> 172.95 | H41: =H39+H40 -> 356.05 | I41: =I39+I40 -> 264.79 | J41: =J39+J40 -> 162.29 | K41: =B41+C41+D41+E41+F41+G41+H41+I41+J41 -> 2026.11
...

Sheet Forecast P&L 2026 1
A2: Projection for the year 2026 (Conservative)
A3: Distribution account | B3: 46023 | C3: 46054 | D3: 46082 | E3: 46113 | F3: 46143 | G3: 46174 | H3: 46204 | I3: 46235 | J3: 46266 | K3: 46296 | L3: 46327 | M3: 46357 | N3: Total
A4: Income
A5: ECOMM PayPal Sales | B5: 13575.9 | C5: 14161.3 | D5: 16279.6 | E5: 11816.7 | F5: 12651.6 | G5: 13008 | H5: 23490.5 | I5: 11091.1 | J5: 8654.4 | K5: 10333.8 | L5: 14941.2 | M5: 10005 | N5: =SUM(B5:M5) -> 160009.1
A6: ECOMM Shopify Sales | B6: 89997.77 | C6: 89941.4 | D6: 89539.3 | E6: 95505.4 | F6: 94595.2 | G6: 93247.4 | H6: 85112.8 | I6: 97195.4 | J6: 71397.7 | K6: 98936 | L6: 91400.3 | M6: 100050 | N6: =SUM(B6:M6) -> 1096918.7
A7: ECOMM Stripe Sales | B7: 10109.68 | C7: 9819.3 | D7: 7783.7 | E7: 7078.9 | F7: 7394.5 | G7: 8626.6 | H7: 6520 | I7: 5972.6 | J7: 6386.8 | K7: 6580.3 | L7: 9740.2 | M7: 6282.2 | N7: =SUM(B7:M7) -> 92294.78
A8: other income | B8: - | C8: - | D8: - | E8: - | F8: - | G8: - | H8: - | I8: - | J8: 29226.3 | K8: - | L8: - | M8: - | N8: =SUM(B8:M8) -> 29226.3
A9: Sales of Product Income | B9: - | C9: - | D9: 559.4 | E9: - | F9: - | G9: - | H9: - | I9: 1106.4 | J9: - | K9: - | L9: - | M9: - | N9: =SUM(B9:M9) -> 1665.8
A10: Sales Tax | B10: - | C10: - | D10: - | E10: - | F10: - | G10: - | H10: - | I10: - | J10: - | K10: - | L10: - | M10: - | N10: -
A11: Total for Income | B11: =Explaination!D63 -> 113683.33 | C11: =B11*100.21% -> 113922.07 | D11: =C11*100.21% -> 114161.3 | E11: =D11*100.21% -> 114401.04 | F11: =E11*100.21% -> 114641.29 | G11: =F11*100.21% -> 114882.03 | H11: =G11*100.21% -> 115123.28 | I11: =H11*100.21% -> 115365.04 | J11: =I11*100.21% -> 115607.31 | ... M11: =L11*100.21% -> 116337.17 | N11: =SUM(B11:M11) -> 1380067.3
A12: Cost of Goods Sold
A13: Cost of Goods Sold | B13: 38546.92 | C13: 20578.3 | D13: 31880.17 | E13: 10777.03 | F13: 17021.22 | G13: 23327.39 | H13: 21673.44 | I13: 25653.65 | J13: 17345.43 | K13: 7027 | L13: 10160.03 | M13: 6803.4 | N13: =SUM(B13:M13) -> 230793.98
A14: Cost of labor - COS | B14: 15124.52 | C14: 29123.35 | D14: 21416.61 | E14: 35812.35 | F14: 36020.81 | G14: 29146.19 | H14: 30368.6 | I14: 29518.71 | J14: 40393.72 | K14: 67276.46 | L14: 62152.21 | M14: 68033.98 | N14: =SUM(B14:M14) -> 464387.51
A15: Freight & Delivery | B15: 23633.23 | C15: 27765.36 | D15: 24332.91 | E15: 31203.33 | F15: 24914.05 | G15: 25646.21 | H15: 26241.8 | I15: 23275.87 | J15: 20873.82 | K15: 4474.59 | L15: 6623.36 | M15: 4271.9 | N15: =SUM(B15:M15) -> 243256.43
A16: Total for Cost of Goods Sold | B16: =B11*68% -> 77304.667 | C16: =C11*68% -> 77467.006 | D16: =D11*68% -> 77629.687 | E16: =E11*68% -> 77792.71 | F16: =F11*68% -> 77956.074 | G16: =G11*68% -> 78119.782 | H16: =H11*68% -> 78283.834 | I16: =I11*68% -> 78448.23 | ... M16: =M11*68% -> 79109.273 | N16: =SUM(B16:M16) -> 938445.78
A17: Gross Profit | B17: =B11-B16 -> 36378.667 | C17: =C11-C16 -> 36455.062 | D17: =D11-D16 -> 36531.618 | E17: =E11-E16 -> 36608.334 | F17: =F11-F16 -> 36685.211 | G17: =G11-G16 -> 36762.25 | H17: =H11-H16 -> 36839.451 | I17: =I11-I16 -> 36916.814 | ... N17: =N11-N16 -> 441621.55
A18: Expenses
A19: Advertising | B19: 4596.65 | C19: 4691.63 | D19: 4344.96 | E19: 4272.29 | F19: 4030.35 | G19: 4545.76 | H19: 3392.88 | I19: 3372.29 | J19: 3155.95 | K19: 3372.29 | L19: 4272.29 | M19: 4545.76 | N19: =SUM(B19:M19) -> 48593.1
A20: Automobile Expense | B20: 451.73 | C20: 423.75 | D20: 424.05 | E20: 269.17 | F20: 1126.87 | G20: 1127.68 | H20: 610.37 | I20: 96.7 | J20: 72.54 | K20: 310.31 | L20: 423.75 | M20: 195.82 | N20: =SUM(B20:M20) -> 5532.74
A21: Gas | B21: 197.57 | C21: 310.31 | D21: 60.81 | E21: 64.6 | F21: 78.48 | G21: 122.47 | H21: 210.63 | I21: 160.48 | J21: 195.82 | K21: 60.81 | L21: 64.6 | M21: 78.48 | N21: =SUM(B21:M21) -> 1605.06
A22: Parking | B22: 11.11 | C22: 15.4 | D22: 32.95 | E22: 18.56 | F22: 15.4 | G22: 5.55 | H22: 24.11 | I22: 5.55 | J22: 32.95 | K22: 15.4 | L22: 32.95 | M22: 24.11 | N22: =SUM(B22:M22) -> 234.04
A23: Total for Automobile Expense | B23: =B20+B21+B22 -> 660.41 | C23: =C20+C21+C22 -> 749.46 | D23: =D20+D21+D22 -> 517.81 | E23: =E20+E21+E22 -> 352.33 | F23: =F20+F21+F22 -> 1220.75 | G23: =G20+G21+G22 -> 1255.7 | H23: =H20+H21+H22 -> 845.11 | I23: =I20+I21+I22 -> 262.73 | ... M23: =M20+M21+M22 -> 298.41 | N23: =SUM(B23:M23) -> 7371.84
A24: Bank Fees | B24: 475.1 | C24: 634.86 | D24: 61.61 | E24: 227.68 | F24: 180.11 | G24: 230.19 | H24: 168.12 | I24: 150.51 | J24: 224.65 | K24: 475.1 | L24: 61.61 | M24: 227.68 | N24: =SUM(B24:M24) -> 3117.22
A25: Charitable & Donations | B25: 89.94 | C25: 90.01 | D25: 168.14 | E25: 78.12 | F25: 90.2 | G25: 90.27 | H25: 90.33 | I25: 90.4 | J25: 90.46 | K25: 90.53 | L25: 90.6 | M25: 90.66 | N25: =SUM(B25:M25) -> 1149.66
A26: Computer Expense | B26: 479.7 | C26: 480.05 | D26: 480.39 | E26: 480.74 | F26: 481.08 | G26: 481.43 | H26: 481.78 | I26: 482.13 | J26: 482.47 | K26: 482.82 | L26: 483.17 | M26: 483.53 | N26: =SUM(B26:M26) -> 5779.29
A27: Dues & Subscriptions | B27: 1683.8 | C27: 1680.17 | D27: 1441.18 | E27: 1622.49 | F27: 1683.79 | G27: 1685.01 | H27: 1686.22 | I27: 1687.44 | J27: 1688.66 | K27: 1689.88 | L27: 1691.11 | M27: 1692.34 | N27: =SUM(B27:M27) -> 19932.09
A28: Entertainment | B28: 1168.27 | C28: 1360.96 | D28: 1078.83 | E28: 2512.6 | F28: 1712.42 | G28: 1711.78 | H28: 2841.96 | I28: 1711.78 | J28: 786.23 | K28: 1711.78 | L28: 1360.96 | M28: 1078.83 | N28: =SUM(B28:M28) -> 19036.4
A29: Insurance | B29: 284.86 | C29: 285.07 | D29: 285.27 | E29: 285.47 | F29: 285.67 | G29: 306.36 | H29: 625.06 | I29: 286.3 | J29: 286.51 | K29: 285.07 | L29: 306.36 | M29: 285.07 | N29: =SUM(B29:M29) -> 3807.07
A30: Interest Expense | B30: 599.63 | C30: 600.06 | D30: 569.49 | E30: 600.92 | F30: 501.35 | G30: 601.79 | H30: 602.22 | I30: 602.66 | J30: 603.09 | K30: 603.53 | L30: 603.97 | M30: 604.41 | N30: =SUM(B30:M30) -> 7093.12
A31: Legal Fees | B31: 474.41 | C31: 3981.09 | D31: 2924.31 | E31: 475.43 | F31: 2344.87 | G31: 474.41 | H31: 975.43 | I31: 2023 | J31: 1884.73 | K31: 3981.09 | L31: 809.5 | M31: 2344.87 | N31: =SUM(B31:M31) -> 22693.14
A32: Lodging | B32: 809.5 | C32: 600.06 | D32: 600.49 | E32: 600.92 | F32: 601.35 | G32: 601.79 | H32: 602.22 | I32: 602.66 | J32: 603.09 | K32: 603.53 | L32: 603.97 | M32: 604.41 | N32: =SUM(B32:M32) -> 7433.99
A33: Marketing | B33: =B11*18% -> 20463 | C33: =C11*18% -> 20505.972 | D33: =D11*18% -> 20549.035 | E33: =E11*18% -> 20592.188 | F33: =F11*18% -> 20635.431 | G33: =G11*18% -> 20678.766 | H33: =H11*18% -> 20722.191 | I33: =I11*18% -> 20765.708 | ... M33: =M11*18% -> 20940.69 | N33: =SUM(B33:M33) -> 248412.12
A34: Meals | B34: 2111.33 | C34: 2922.88 | D34: 2924.98 | E34: 4201.95 | F34: 4216.46 | G34: 3338.99 | H34: 2120.45 | I34: 4298.23 | J34: 2525.28 | K34: 2111.33 | L34: 4216.46 | M34: 2924.98 | N34: =SUM(B34:M34) -> 37913.32
A35: Medical | B35: 312 | C35: 312.22 | D35: 271.68 | E35: 88.29 | F35: 74.06 | G35: 88.29 | H35: 74.06 | I35: 88.29 | J35: 312 | K35: 271.68 | L35: 312 | M35: 271.68 | N35: =SUM(B35:M35) -> 2476.25
A36: Membership | B36: 328.97 | C36: 159.41 | D36: 922.54 | E36: 1703.39 | F36: 336.78 | G36: 480.92 | H36: 337.26 | I36: 865.05 | J36: 351.37 | K36: 336.78 | L36: 337.26 | M36: 336.78 | N36: =SUM(B36:M36) -> 6496.51
A37: Merchant Fees | B37: 256.72 | C37: 243.52 | D37: 251.02 | E37: 362.86 | F37: 240.81 | G37: 185.55 | H37: 260.1 | I37: 258.02 | J37: 258.2 | K37: 258.39 | L37: 258.58 | M37: 258.77 | N37: =SUM(B37:M37) -> 3092.54
A38: Stripe Fee | B38: 98.53 | C38: 98.6 | D38: 98.67 | E38: 98.74 | F38: 98.81 | G38: 98.88 | H38: 98.95 | I38: 103.03 | J38: 99.1 | K38: 99.17 | L38: 99.24 | M38: 99.31 | N38: =SUM(B38:M38) -> 1191.03
A39: Total for Merchant Fees | B39: =B37+B38 -> 355.25 | C39: =C37+C38 -> 342.12 | D39: =D37+D38 -> 349.69 | E39: =E37+E38 -> 461.6 | F39: =F37+F38 -> 339.62 | G39: =G37+G38 -> 284.43 | H39: =H37+H38 -> 359.05 | I39: =I37+I38 -> 361.05 | ... M39: =M37+M38 -> 358.08 | N39: =SUM(B39:M39) -> 4283.57
A40: Miscellaneous | B40: 75.91 | C40: 401.28 | D40: 401.57 | E40: 385.86 | F40: 834.26 | G40: 569.21 | H40: 569.63 | I40: 1553.86 | J40: 157.19 | K40: 157.3 | L40: 157.41 | M40: 571.69 | N40: =SUM(B40:M40) -> 5835.17
A41: Office Expense | B41: 4775.42 | C41: 3307.59 | D41: 3309.96 | E41: 3302.34 | F41: 4580.6 | G41: 6447.72 | H41: 4580.6 | I41: 4290.42 | J41: 5431.48 | K41: 3302.34 | L41: 3243.59 | M41: 3272.34 | N41: =SUM(B41:M41) -> 49844.4
...

Sheet Forecast P&L 2026 2
A2: Projection for the year 2026 (Base)
A3: Distribution account | B3: 46023 | C3: 46054 | D3: 46082 | E3: 46113 | F3: 46143 | G3: 46174 | H3: 46204 | I3: 46235 | J3: 46266 | K3: 46296 | L3: 46327 | M3: 46357 | N3: Total
A4: Income
A5: ECOMM PayPal Sales | B5: 14944.22 | C5: 15613.53 | D5: 17977.74 | E5: 13070.12 | F5: 14015.92 | G5: 14433.79 | H5: 26106.86 | I5: 12346.07 | J5: 9649.06 | K5: 11539.9 | L5: 16711.67 | M5: 11208.4 | N5: =SUM(B5:M5) -> 177617.28
A6: ECOMM Shopify Sales | B6: 99068.8 | C6: 99164.87 | D6: 98879.11 | E6: 105635.96 | F6: 104796.24 | G6: 103468 | H6: 94592.61 | I6: 108193.41 | J6: 79603.47 | K6: 110482.91 | L6: 102230.72 | M6: 112083.98 | N6: =SUM(B6:M6) -> 1218200.1
A7: ECOMM Stripe Sales | B7: 11128.65 | C7: 10826.29 | D7: 8595.6 | E7: 7829.81 | F7: 8191.91 | G7: 9572.2 | H7: 7246.17 | I7: 6648.42 | J7: 7120.88 | K7: 7348.28 | L7: 10894.4 | M7: 7037.83 | N7: =SUM(B7:M7) -> 102440.44
A8: other income | B8: - | C8: - | D8: - | E8: - | F8: - | G8: - | H8: - | I8: - | J8: 32585.34 | K8: - | L8: - | M8: - | N8: =SUM(B8:M8) -> 32585.34
A9: Sales of Product Income | B9: - | C9: - | D9: 617.74 | E9: - | F9: - | G9: - | H9: - | I9: 1231.54 | J9: - | K9: - | L9: - | M9: - | N9: =SUM(B9:M9) -> 1849.28
A10: Sales Tax | B10: - | C10: - | D10: - | E10: - | F10: - | G10: - | H10: - | I10: - | J10: - | K10: - | L10: - | M10: - | N10: -
A11: Total for Income | B11: =Explaination!E63 -> 125141.67 | C11: =B11*100.37% -> 125604.69 | D11: =C11*100.37% -> 126069.43 | E11: =D11*100.37% -> 126535.89 | F11: =E11*100.37% -> 127004.07 | G11: =F11*100.37% -> 127473.98 | H11: =G11*100.37% -> 127945.64 | I11: =H11*100.37% -> 128419.04 | J11: =I11*100.37% -> 128894.19 | ... M11: =L11*100.37% -> 130330.21 | N11: =SUM(B11:M11) -> 1532639.7
A12: Cost of Goods Sold
A13: Cost of Goods Sold | B13: 42432.13 | C13: 22688.59 | D13: 35205.57 | E13: 11920.18 | F13: 18856.77 | G13: 25884.25 | H13: 24087.41 | I13: 28556.46 | J13: 19338.96 | K13: 7847.13 | L13: 11363.93 | M13: 7621.71 | N13: =SUM(B13:M13) -> 255803.09
A14: Cost of labor - COS | B14: 16648.94 | C14: 32109.93 | D14: 23650.57 | E14: 39611.07 | F14: 39905.25 | G14: 32340.83 | H14: 33751.03 | I14: 32858.87 | J14: 45036.21 | K14: 75128.38 | L14: 69516.89 | M14: 76217.11 | N14: =SUM(B14:M14) -> 516775.08
A15: Freight & Delivery | B15: 26015.26 | C15: 30612.67 | D15: 26871.07 | E15: 34513.15 | F15: 27600.75 | G15: 28457.23 | H15: 29164.59 | I15: 25909.62 | J15: 23272.88 | K15: 4996.83 | L15: 7408.19 | M15: 4785.73 | N15: =SUM(B15:M15) -> 269607.97
A16: Total for Cost of Goods Sold | B16: =B11*68% -> 85096.333 | C16: =C11*68% -> 85411.19 | D16: =D11*68% -> 85727.211 | E16: =E11*68% -> 86044.402 | F16: =F11*68% -> 86362.766 | G16: =G11*68% -> 86682.308 | H16: =H11*68% -> 87003.033 | I16: =I11*68% -> 87324.944 | ... M16: =M11*68% -> 88624.544 | N16: =SUM(B16:M16) -> 1042195
A17: Gross Profit | B17: =B11-B16 -> 40045.333 | C17: =C11-C16 -> 40193.501 | D17: =D11-D16 -> 40342.217 | E17: =E11-E16 -> 40491.483 | F17: =F11-F16 -> 40641.302 | G17: =G11-G16 -> 40791.675 | H17: =H11-H16 -> 40942.604 | I17: =I11-I16 -> 41094.091 | ... N17: =N11-N16 -> 490444.69
A18: Expenses
A19: Advertising | B19: 4754.76 | C19: 4282.91 | D19: 4754.76 | E19: 4545.76 | F19: 4272.29 | G19: 3155.95 | H19: 4282.91 | I19: 4030.35 | J19: 3155.95 | K19: 4307.62 | L19: 4754.76 | M19: 4272.29 | N19: =SUM(B19:M19) -> 50570.31
A20: Automobile Expense | B20: 424.05 | C20: 807.41 | D20: 610.37 | E20: 1127.68 | F20: 423.75 | G20: 72.54 | H20: 812.89 | I20: 1126.87 | J20: 72.54 | K20: 816.23 | L20: 424.05 | M20: 423.75 | N20: =SUM(B20:M20) -> 7142.13
A21: Gas | B21: 60.81 | C21: 621.09 | D21: 210.63 | E21: 122.47 | F21: 64.6 | G21: 195.82 | H21: 625.3 | I21: 78.48 | J21: 195.82 | K21: 627.87 | L21: 60.81 | M21: 64.6 | N21: =SUM(B21:M21) -> 2928.3
A22: Parking | B22: 32.95 | C22: 62.11 | D22: 24.11 | E22: 5.55 | F22: 32.95 | G22: 32.95 | H22: 62.53 | I22: 15.4 | J22: 32.95 | K22: 62.79 | L22: 32.95 | M22: 32.95 | N22: =SUM(B22:M22) -> 430.19
A23: Total for Automobile Expense | B23: =B20+B21+B22 -> 517.81 | C23: =C20+C21+C22 -> 1490.61 | D23: =D20+D21+D22 -> 845.11 | E23: =E20+E21+E22 -> 1255.7 | F23: =F20+F21+F22 -> 521.3 | G23: =G20+G21+G22 -> 301.31 | H23: =H20+H21+H22 -> 1500.72 | I23: =I20+I21+I22 -> 1220.75 | ... M23: =M20+M21+M22 -> 521.3 | N23: =SUM(B23:M23) -> 10500.62
A24: Bank Fees | B24: 475.1 | C24: 227.68 | D24: 168.12 | E24: 230.19 | F24: 61.61 | G24: 224.65 | H24: 250.12 | I24: 180.11 | J24: 224.65 | K24: 251.15 | L24: 475.1 | M24: 61.61 | N24: =SUM(B24:M24) -> 2830.09
A25: Charitable & Donations | B25: 89.94 | C25: 90.66 | D25: 90.33 | E25: 90.27 | F25: 90.6 | G25: 90.46 | H25: 90.27 | I25: 90.2 | J25: 90.46 | K25: 816.23 | L25: 89.94 | M25: 90.6 | N25: =SUM(B25:M25) -> 1809.96
A26: Computer Expense | B26: 479.7 | C26: 483.53 | D26: 481.78 | E26: 481.43 | F26: 483.17 | G26: 482.47 | H26: 781.63 | I26: 481.08 | J26: 482.47 | K26: 816.23 | L26: 479.7 | M26: 483.17 | N26: =SUM(B26:M26) -> 6416.36
A27: Dues & Subscriptions | B27: 1683.8 | C27: 1522.34 | D27: 1686.22 | E27: 1685.01 | F27: 1691.11 | G27: 1688.66 | H27: 781.63 | I27: 1683.79 | J27: 1688.66 | K27: 816.23 | L27: 1683.8 | M27: 1691.11 | N27: =SUM(B27:M27) -> 18302.36
A28: Entertainment | B28: 1168.27 | C28: 1078.83 | D28: 2841.96 | E28: 1711.78 | F28: 1360.96 | G28: 786.23 | H28: 781.63 | I28: 1712.42 | J28: 786.23 | K28: 816.23 | L28: 1168.27 | M28: 1360.96 | N28: =SUM(B28:M28) -> 15573.77
A29: Insurance | B29: 284.86 | C29: 285.07 | D29: 625.06 | E29: 306.36 | F29: 306.36 | G29: 286.51 | H29: 286.51 | I29: 285.67 | J29: 286.51 | K29: 816.23 | L29: 284.86 | M29: 306.36 | N29: =SUM(B29:M29) -> 4360.36
A30: Interest Expense | B30: 599.63 | C30: 604.41 | D30: 602.22 | E30: 601.79 | F30: 603.97 | G30: 603.09 | H30: 781.63 | I30: 501.35 | J30: 603.09 | K30: 816.23 | L30: 599.63 | M30: 603.97 | N30: =SUM(B30:M30) -> 7521.01
A31: Legal Fees | B31: 474.41 | C31: 2344.87 | D31: 975.43 | E31: 474.41 | F31: 809.5 | G31: 1884.73 | H31: 1250.6 | I31: 2344.87 | J31: 1884.73 | K31: 1255.74 | L31: 474.41 | M31: 809.5 | N31: =SUM(B31:M31) -> 14983.2
A32: Lodging | B32: 809.5 | C32: 604.41 | D32: 602.22 | E32: 601.79 | F32: 603.97 | G32: 603.09 | H32: 781.63 | I32: 601.35 | J32: 603.09 | K32: 816.23 | L32: 809.5 | M32: 603.97 | N32: =SUM(B32:M32) -> 8040.75
A33: Marketing | B33: =B11*18% -> 22525.5 | C33: =C11*18% -> 22608.844 | D33: =D11*18% -> 22692.497 | E33: =E11*18% -> 22776.459 | F33: =F11*18% -> 22860.732 | G33: =G11*18% -> 22945.317 | H33: =H11*18% -> 23030.215 | I33: =I11*18% -> 23115.426 | ... M33: =M11*18% -> 23459.438 | N33: =SUM(B33:M33) -> 275875.14
